Workbook
Name Pekerjaanutama: #REF!
Name Penghasilan: #REF!
Name PNS: #REF!
Name PNS: #REF!
Name PNS: #REF!
Name PNS: #REF!
Name PNS: #REF!
Name PNS: #REF!
Name PNS: #REF!
Name PNS: #REF!

Sheet IDENTITAS PENGHUNI RUMAH 1
A1: REKAP PENDATAAN RUMAH TIDAK LAYAK HUNI
A3: Provinsi | C3: Sumatera Selatan
A4: Kota | C4: Palembang
A5: Kecamatan | C5: Plaju
A6: Kelurahan | C6: Talang Putri
A7: Tanggal Pendataan
A9: No | B9: Nama Kepala Rumah Tangga | C9: IDENTITAS PENGHUNI RUMAH
C10: NIK | D10: Alamat | E10: RT/RW | F10: Usia (Th) | G10: Pendidikan Terkahir | H10: Jenis Kelamin | I10: Pekerjaan Utama | J10: Penghasilan Per bulan
A12: 1 | B12: Sutamak | C12: 1671140605720003 | D12: Lrg. Hikmah II | E12: RT24 RW06 | F12: 61 | G12: SD/Sederajat | H12: L | I12: Buruh Harian | J12: 1.9 – 2.1 juta
A13: =1+A12 -> 2 | B13: Mawarni | C13: 1671147006690001 | D13: Lrg. Hikmah II | E13: RT 24 / RW 06 | F13: 52 | G13: SD/Sederajat | H13: P | I13: Buruh Harian | J13: < 1.2 juta
A14: =1+A13 -> 3 | B14: Samsila | C14: 1.671145e+15 | D14: Jl. Kapten Robani Kader | E14: RT 22 / RW 06 | F14: 56 | G14: SD/Sederajat | H14: P | I14: Tidak Bekerja | J14: < 1.2 juta
A15: =1+A14 -> 4 | B15: Sumirah | C15: 1671146808630004 | D15: Jl. Kapten Robani Kader | E15: RT 22 / RW 06 | F15: 60 | G15: SD/Sederajat | H15: P | I15: Wirausaha | J15: < 1.2 juta
A16: =1+A15 -> 5 | B16: M. Daud | C16: 1.6711405e+15 | D16: Lr. Karya Luhur | E16: RT 25 RW 06 | F16: 64 | G16: SD/Sederajat | H16: L | I16: Tidak Bekerja | J16: < 1.2 juta
A17: =1+A16 -> 6 | B17: Salam Hadi | C17: 1671141012660005 | D17: Lrg. Hikmah I | E17: RT 09 RW 03 | F17: 57 | G17: SD/Sederajat | H17: L | I17: Buruh Harian | J17: < 1.2 juta
A18: =1+A17 -> 7 | B18: Sukandar | C18: 1671142101560003 | D18: Lr. Sidomulyo | E18: RT12 / RW04 | F18: 67 | G18: D1/D2/D3 | H18: L | I18: Buruh Harian | J18: < 1.2 juta
A19: =1+A18 -> 8 | B19: Sagiman | C19: 1671141408520004 | D19: Lr.Sidokaton II | E19: RT09 / RW00 | F19: 70 | G19: SD/Sederajat | H19: L | I19: Tukang/Montir | J19: < 1.2 juta
A20: =1+A19 -> 9 | B20: Daryuni | C20: 1671145709480003 | D20: Lr. Karya Luhur | E20: RT 25 RW 06 | F20: 75 | G20: SD/Sederajat | H20: P | I20: Tidak Bekerja | J20: < 1.2 juta
A21: =1+A20 -> 10
A22: =1+A21 -> 11
A23: =1+A22 -> 12
A24: =1+A23 -> 13
A25: =1+A24 -> 14
A26: =1+A25 -> 15
A27: =1+A26 -> 16
A28: =1+A27 -> 17
A29: =1+A28 -> 18
A30: =1+A29 -> 19
A31: =1+A30 -> 20
A32: =1+A31 -> 21
... A111: =1+A110 -> 100

Sheet IDENTITAS PENGHUNI RUMAH 2
A1: REKAP PENDATAAN RUMAH TIDAK LAYAK HUNI
A3: ='IDENTITAS PENGHUNI RUMAH 1'!A3 -> Provinsi | C3: ='IDENTITAS PENGHUNI RUMAH 1'!C3 -> Sumatera Selatan
A4: ='IDENTITAS PENGHUNI RUMAH 1'!A4 -> Kota | C4: ='IDENTITAS PENGHUNI RUMAH 1'!C4 -> Palembang
A5: ='IDENTITAS PENGHUNI RUMAH 1'!A5 -> Kecamatan | C5: ='IDENTITAS PENGHUNI RUMAH 1'!C5 -> Plaju
A6: ='IDENTITAS PENGHUNI RUMAH 1'!A6 -> Kelurahan | C6: ='IDENTITAS PENGHUNI RUMAH 1'!C6 -> Talang Putri
A7: ='IDENTITAS PENGHUNI RUMAH 1'!A7 -> Tanggal Pendataan | C7: ='IDENTITAS PENGHUNI RUMAH 1'!C7 -> 0
A9: No | B9: Nama Kepala Rumah Tangga | C9: IDENTITAS PENGHUNI RUMAH
C10: NIK | D10: Alamat | E10: RT/RW | F10: Status Kepemilikan Tanah | G10: Status Kepemilikan Rumah | H10: Aset Rumah Ditempat Lain | I10: Aset Tanah Ditempat Lain
A12: ='IDENTITAS PENGHUNI RUMAH 1'!A12 -> 1 | B12: ='IDENTITAS PENGHUNI RUMAH 1'!B12 -> Sutamak | C12: ='IDENTITAS PENGHUNI RUMAH 1'!C12 -> 1671140605720003 | D12: ='IDENTITAS PENGHUNI RUMAH 1'!D12 -> Lrg. Hikmah II | E12: ='IDENTITAS PENGHUNI RUMAH 1'!E12 -> RT24 RW06 | F12: Milik Sendiri | G12: Milik Sendiri | H12: Tidak Ada | I12: Tidak Ada
A13: ='IDENTITAS PENGHUNI RUMAH 1'!A13 -> 2 | B13: ='IDENTITAS PENGHUNI RUMAH 1'!B13 -> Mawarni | C13: ='IDENTITAS PENGHUNI RUMAH 1'!C13 -> 1671147006690001 | D13: ='IDENTITAS PENGHUNI RUMAH 1'!D13 -> Lrg. Hikmah II | E13: ='IDENTITAS PENGHUNI RUMAH 1'!E13 -> RT 24 / RW 06 | F13: Milik Sendiri | G13: Milik Sendiri | H13: Tidak Ada | I13: Tidak Ada
A14: ='IDENTITAS PENGHUNI RUMAH 1'!A14 -> 3 | B14: ='IDENTITAS PENGHUNI RUMAH 1'!B14 -> Samsila | C14: ='IDENTITAS PENGHUNI RUMAH 1'!C14 -> 1.671145e+15 | D14: ='IDENTITAS PENGHUNI RUMAH 1'!D14 -> Jl. Kapten Robani Kader | E14: ='IDENTITAS PENGHUNI RUMAH 1'!E14 -> RT 22 / RW 06 | F14: Milik Sendiri | G14: Milik Sendiri | H14: Tidak Ada | I14: Tidak Ada
A15: ='IDENTITAS PENGHUNI RUMAH 1'!A15 -> 4 | B15: ='IDENTITAS PENGHUNI RUMAH 1'!B15 -> Sumirah | C15: ='IDENTITAS PENGHUNI RUMAH 1'!C15 -> 1671146808630004 | D15: ='IDENTITAS PENGHUNI RUMAH 1'!D15 -> Jl. Kapten Robani Kader | E15: ='IDENTITAS PENGHUNI RUMAH 1'!E15 -> RT 22 / RW 06 | F15: Milik Sendiri | G15: Milik Sendiri | H15: Tidak Ada | I15: Tidak Ada
A16: ='IDENTITAS PENGHUNI RUMAH 1'!A16 -> 5 | B16: ='IDENTITAS PENGHUNI RUMAH 1'!B16 -> M. Daud | C16: ='IDENTITAS PENGHUNI RUMAH 1'!C16 -> 1.6711405e+15 | D16: ='IDENTITAS PENGHUNI RUMAH 1'!D16 -> Lr. Karya Luhur | E16: ='IDENTITAS PENGHUNI RUMAH 1'!E16 -> RT 25 RW 06 | F16: Milik Sendiri | G16: Milik Sendiri | H16: Tidak Ada | I16: Tidak Ada
A17: ='IDENTITAS PENGHUNI RUMAH 1'!A17 -> 6 | B17: ='IDENTITAS PENGHUNI RUMAH 1'!B17 -> Salam Hadi | C17: ='IDENTITAS PENGHUNI RUMAH 1'!C17 -> 1671141012660005 | D17: ='IDENTITAS PENGHUNI RUMAH 1'!D17 -> Lrg. Hikmah I | E17: ='IDENTITAS PENGHUNI RUMAH 1'!E17 -> RT 09 RW 03 | F17: Milik Sendiri | G17: Milik Sendiri | H17: Tidak Ada | I17: Tidak Ada
A18: ='IDENTITAS PENGHUNI RUMAH 1'!A18 -> 7 | B18: ='IDENTITAS PENGHUNI RUMAH 1'!B18 -> Sukandar | C18: ='IDENTITAS PENGHUNI RUMAH 1'!C18 -> 1671142101560003 | D18: ='IDENTITAS PENGHUNI RUMAH 1'!D18 -> Lr. Sidomulyo | E18: ='IDENTITAS PENGHUNI RUMAH 1'!E18 -> RT12 / RW04 | F18: Milik Sendiri | G18: Milik Sendiri | H18: Tidak Ada | I18: Tidak Ada
A19: ='IDENTITAS PENGHUNI RUMAH 1'!A19 -> 8 | B19: ='IDENTITAS PENGHUNI RUMAH 1'!B19 -> Sagiman | C19: ='IDENTITAS PENGHUNI RUMAH 1'!C19 -> 1671141408520004 | D19: ='IDENTITAS PENGHUNI RUMAH 1'!D19 -> Lr.Sidokaton II | E19: ='IDENTITAS PENGHUNI RUMAH 1'!E19 -> RT09 / RW00 | F19: Milik Sendiri | G19: Milik Sendiri | H19: Tidak Ada | I19: Tidak Ada
A20: ='IDENTITAS PENGHUNI RUMAH 1'!A20 -> 9 | B20: ='IDENTITAS PENGHUNI RUMAH 1'!B20 -> Daryuni | C20: ='IDENTITAS PENGHUNI RUMAH 1'!C20 -> 1671145709480003 | D20: ='IDENTITAS PENGHUNI RUMAH 1'!D20 -> Lr. Karya Luhur | E20: ='IDENTITAS PENGHUNI RUMAH 1'!E20 -> RT 25 RW 06 | F20: Milik Sendiri | G20: Milik Sendiri | H20: Tidak Ada | I20: Tidak Ada
A21: ='IDENTITAS PENGHUNI RUMAH 1'!A21 -> 10 | B21: ='IDENTITAS PENGHUNI RUMAH 1'!B21 -> 0 | C21: ='IDENTITAS PENGHUNI RUMAH 1'!C21 -> 0 | D21: ='IDENTITAS PENGHUNI RUMAH 1'!D21 -> 0 | E21: ='IDENTITAS PENGHUNI RUMAH 1'!E21 -> 0
A22: ='IDENTITAS PENGHUNI RUMAH 1'!A22 -> 11 | B22: ='IDENTITAS PENGHUNI RUMAH 1'!B22 -> 0 | C22: ='IDENTITAS PENGHUNI RUMAH 1'!C22 -> 0 | D22: ='IDENTITAS PENGHUNI RUMAH 1'!D22 -> 0 | E22: ='IDENTITAS PENGHUNI RUMAH 1'!E22 -> 0
A23: ='IDENTITAS PENGHUNI RUMAH 1'!A23 -> 12 | B23: ='IDENTITAS PENGHUNI RUMAH 1'!B23 -> 0 | C23: ='IDENTITAS PENGHUNI RUMAH 1'!C23 -> 0 | D23: ='IDENTITAS PENGHUNI RUMAH 1'!D23 -> 0 | E23: ='IDENTITAS PENGHUNI RUMAH 1'!E23 -> 0
A24: ='IDENTITAS PENGHUNI RUMAH 1'!A24 -> 13 | B24: ='IDENTITAS PENGHUNI RUMAH 1'!B24 -> 0 | C24: ='IDENTITAS PENGHUNI RUMAH 1'!C24 -> 0 | D24: ='IDENTITAS PENGHUNI RUMAH 1'!D24 -> 0 | E24: ='IDENTITAS PENGHUNI RUMAH 1'!E24 -> 0
A25: ='IDENTITAS PENGHUNI RUMAH 1'!A25 -> 14 | B25: ='IDENTITAS PENGHUNI RUMAH 1'!B25 -> 0 | C25: ='IDENTITAS PENGHUNI RUMAH 1'!C25 -> 0 | D25: ='IDENTITAS PENGHUNI RUMAH 1'!D25 -> 0 | E25: ='IDENTITAS PENGHUNI RUMAH 1'!E25 -> 0
A26: ='IDENTITAS PENGHUNI RUMAH 1'!A26 -> 15 | B26: ='IDENTITAS PENGHUNI RUMAH 1'!B26 -> 0 | C26: ='IDENTITAS PENGHUNI RUMAH 1'!C26 -> 0 | D26: ='IDENTITAS PENGHUNI RUMAH 1'!D26 -> 0 | E26: ='IDENTITAS PENGHUNI RUMAH 1'!E26 -> 0
A27: ='IDENTITAS PENGHUNI RUMAH 1'!A27 -> 16 | B27: ='IDENTITAS PENGHUNI RUMAH 1'!B27 -> 0 | C27: ='IDENTITAS PENGHUNI RUMAH 1'!C27 -> 0 | D27: ='IDENTITAS PENGHUNI RUMAH 1'!D27 -> 0 | E27: ='IDENTITAS PENGHUNI RUMAH 1'!E27 -> 0
A28: ='IDENTITAS PENGHUNI RUMAH 1'!A28 -> 17 | B28: ='IDENTITAS PENGHUNI RUMAH 1'!B28 -> 0 | C28: ='IDENTITAS PENGHUNI RUMAH 1'!C28 -> 0 | D28: ='IDENTITAS PENGHUNI RUMAH 1'!D28 -> 0 | E28: ='IDENTITAS PENGHUNI RUMAH 1'!E28 -> 0
A29: ='IDENTITAS PENGHUNI RUMAH 1'!A29 -> 18 | B29: ='IDENTITAS PENGHUNI RUMAH 1'!B29 -> 0 | C29: ='IDENTITAS PENGHUNI RUMAH 1'!C29 -> 0 | D29: ='IDENTITAS PENGHUNI RUMAH 1'!D29 -> 0 | E29: ='IDENTITAS PENGHUNI RUMAH 1'!E29 -> 0
A30: ='IDENTITAS PENGHUNI RUMAH 1'!A30 -> 19 | B30: ='IDENTITAS PENGHUNI RUMAH 1'!B30 -> 0 | C30: ='IDENTITAS PENGHUNI RUMAH 1'!C30 -> 0 | D30: ='IDENTITAS PENGHUNI RUMAH 1'!D30 -> 0 | E30: ='IDENTITAS PENGHUNI RUMAH 1'!E30 -> 0
A31: ='IDENTITAS PENGHUNI RUMAH 1'!A31 -> 20 | B31: ='IDENTITAS PENGHUNI RUMAH 1'!B31 -> 0 | C31: ='IDENTITAS PENGHUNI RUMAH 1'!C31 -> 0 | D31: ='IDENTITAS PENGHUNI RUMAH 1'!D31 -> 0 | E31: ='IDENTITAS PENGHUNI RUMAH 1'!E31 -> 0
A32: ='IDENTITAS PENGHUNI RUMAH 1'!A32 -> 21 | B32: ='IDENTITAS PENGHUNI RUMAH 1'!B32 -> 0 | C32: ='IDENTITAS PENGHUNI RUMAH 1'!C32 -> 0 | D32: ='IDENTITAS PENGHUNI RUMAH 1'!D32 -> 0 | E32: ='IDENTITAS PENGHUNI RUMAH 1'!E32 -> 0
... A111: ='IDENTITAS PENGHUNI RUMAH 1'!A111 -> 100 | B111: ='IDENTITAS PENGHUNI RUMAH 1'!B111 -> 0 | C111: ='IDENTITAS PENGHUNI RUMAH 1'!C111 -> 0 | D111: ='IDENTITAS PENGHUNI RUMAH 1'!D111 -> 0 | E111: ='IDENTITAS PENGHUNI RUMAH 1'!E111 -> 0

Sheet IDENTITAS PENGHUNI RUMAH 2 (2)
A1: REKAP PENDATAAN RUMAH TIDAK LAYAK HUNI
A3: ='IDENTITAS PENGHUNI RUMAH 1'!A3 -> Provinsi | C3: ='IDENTITAS PENGHUNI RUMAH 1'!C3 -> Sumatera Selatan
A4: ='IDENTITAS PENGHUNI RUMAH 1'!A4 -> Kota | C4: ='IDENTITAS PENGHUNI RUMAH 1'!C4 -> Palembang
A5: ='IDENTITAS PENGHUNI RUMAH 1'!A5 -> Kecamatan | C5: ='IDENTITAS PENGHUNI RUMAH 1'!C5 -> Plaju
A6: ='IDENTITAS PENGHUNI RUMAH 1'!A6 -> Kelurahan | C6: ='IDENTITAS PENGHUNI RUMAH 1'!C6 -> Talang Putri
A7: ='IDENTITAS PENGHUNI RUMAH 1'!A7 -> Tanggal Pendataan | C7: ='IDENTITAS PENGHUNI RUMAH 1'!C7 -> 0
A9: No | B9: Nama Kepala Rumah Tangga | C9: IDENTITAS PENGHUNI RUMAH
C10: NIK | D10: Alamat | E10: RT/RW | F10: Pernah Mendapatkan Bantuan Pemerintah | G10: Jenis Kawasan Lokasi Rumah yang Ditempati
A12: ='IDENTITAS PENGHUNI RUMAH 2'!A12 -> 1 | B12: ='IDENTITAS PENGHUNI RUMAH 2'!B12 -> Sutamak | C12: ='IDENTITAS PENGHUNI RUMAH 2'!C12 -> 1671140605720003 | D12: ='IDENTITAS PENGHUNI RUMAH 2'!D12 -> Lrg. Hikmah II | E12: ='IDENTITAS PENGHUNI RUMAH 2'!E12 -> RT24 RW06 | F12: Belum Pernah | G12: Perbatasan
A13: ='IDENTITAS PENGHUNI RUMAH 2'!A13 -> 2 | B13: ='IDENTITAS PENGHUNI RUMAH 2'!B13 -> Mawarni | C13: ='IDENTITAS PENGHUNI RUMAH 2'!C13 -> 1671147006690001 | D13: ='IDENTITAS PENGHUNI RUMAH 2'!D13 -> Lrg. Hikmah II | E13: ='IDENTITAS PENGHUNI RUMAH 2'!E13 -> RT 24 / RW 06 | F13: Belum Pernah | G13: Perbatasan
A14: ='IDENTITAS PENGHUNI RUMAH 2'!A14 -> 3 | B14: ='IDENTITAS PENGHUNI RUMAH 2'!B14 -> Samsila | C14: ='IDENTITAS PENGHUNI RUMAH 2'!C14 -> 1.671145e+15 | D14: ='IDENTITAS PENGHUNI RUMAH 2'!D14 -> Jl. Kapten Robani Kader | E14: ='IDENTITAS PENGHUNI RUMAH 2'!E14 -> RT 22 / RW 06 | F14: Belum Pernah | G14: Perbatasan
A15: ='IDENTITAS PENGHUNI RUMAH 2'!A15 -> 4 | B15: ='IDENTITAS PENGHUNI RUMAH 2'!B15 -> Sumirah | C15: ='IDENTITAS PENGHUNI RUMAH 2'!C15 -> 1671146808630004 | D15: ='IDENTITAS PENGHUNI RUMAH 2'!D15 -> Jl. Kapten Robani Kader | E15: ='IDENTITAS PENGHUNI RUMAH 2'!E15 -> RT 22 / RW 06 | F15: Belum Pernah | G15: Rawan Air
A16: ='IDENTITAS PENGHUNI RUMAH 2'!A16 -> 5 | B16: ='IDENTITAS PENGHUNI RUMAH 2'!B16 -> M. Daud | C16: ='IDENTITAS PENGHUNI RUMAH 2'!C16 -> 1.6711405e+15 | D16: ='IDENTITAS PENGHUNI RUMAH 2'!D16 -> Lr. Karya Luhur | E16: ='IDENTITAS PENGHUNI RUMAH 2'!E16 -> RT 25 RW 06 | F16: Belum Pernah | G16: Kumuh
A17: ='IDENTITAS PENGHUNI RUMAH 2'!A17 -> 6 | B17: ='IDENTITAS PENGHUNI RUMAH 2'!B17 -> Salam Hadi | C17: ='IDENTITAS PENGHUNI RUMAH 2'!C17 -> 1671141012660005 | D17: ='IDENTITAS PENGHUNI RUMAH 2'!D17 -> Lrg. Hikmah I | E17: ='IDENTITAS PENGHUNI RUMAH 2'!E17 -> RT 09 RW 03 | F17: Belum Pernah | G17: Rawan Air
A18: ='IDENTITAS PENGHUNI RUMAH 2'!A18 -> 7 | B18: ='IDENTITAS PENGHUNI RUMAH 2'!B18 -> Sukandar | C18: ='IDENTITAS PENGHUNI RUMAH 2'!C18 -> 1671142101560003 | D18: ='IDENTITAS PENGHUNI RUMAH 2'!D18 -> Lr. Sidomulyo | E18: ='IDENTITAS PENGHUNI RUMAH 2'!E18 -> RT12 / RW04 | F18: Belum Pernah | G18: Perbatasan
A19: ='IDENTITAS PENGHUNI RUMAH 2'!A19 -> 8 | B19: ='IDENTITAS PENGHUNI RUMAH 2'!B19 -> Sagiman | C19: ='IDENTITAS PENGHUNI RUMAH 2'!C19 -> 1671141408520004 | D19: ='IDENTITAS PENGHUNI RUMAH 2'!D19 -> Lr.Sidokaton II | E19: ='IDENTITAS PENGHUNI RUMAH 2'!E19 -> RT09 / RW00 | F19: Belum Pernah | G19: Perbatasan
A20: ='IDENTITAS PENGHUNI RUMAH 2'!A20 -> 9 | B20: ='IDENTITAS PENGHUNI RUMAH 2'!B20 -> Daryuni | C20: ='IDENTITAS PENGHUNI RUMAH 2'!C20 -> 1671145709480003 | D20: ='IDENTITAS PENGHUNI RUMAH 2'!D20 -> Lr. Karya Luhur | E20: ='IDENTITAS PENGHUNI RUMAH 2'!E20 -> RT 25 RW 06 | F20: Belum Pernah | G20: Perbatasan
A21: ='IDENTITAS PENGHUNI RUMAH 2'!A21 -> 10 | B21: ='IDENTITAS PENGHUNI RUMAH 2'!B21 -> 0 | C21: ='IDENTITAS PENGHUNI RUMAH 2'!C21 -> 0 | D21: ='IDENTITAS PENGHUNI RUMAH 2'!D21 -> 0 | E21: ='IDENTITAS PENGHUNI RUMAH 2'!E21 -> 0
A22: ='IDENTITAS PENGHUNI RUMAH 2'!A22 -> 11 | B22: ='IDENTITAS PENGHUNI RUMAH 2'!B22 -> 0 | C22: ='IDENTITAS PENGHUNI RUMAH 2'!C22 -> 0 | D22: ='IDENTITAS PENGHUNI RUMAH 2'!D22 -> 0 | E22: ='IDENTITAS PENGHUNI RUMAH 2'!E22 -> 0
A23: ='IDENTITAS PENGHUNI RUMAH 2'!A23 -> 12 | B23: ='IDENTITAS PENGHUNI RUMAH 2'!B23 -> 0 | C23: ='IDENTITAS PENGHUNI RUMAH 2'!C23 -> 0 | D23: ='IDENTITAS PENGHUNI RUMAH 2'!D23 -> 0 | E23: ='IDENTITAS PENGHUNI RUMAH 2'!E23 -> 0
A24: ='IDENTITAS PENGHUNI RUMAH 2'!A24 -> 13 | B24: ='IDENTITAS PENGHUNI RUMAH 2'!B24 -> 0 | C24: ='IDENTITAS PENGHUNI RUMAH 2'!C24 -> 0 | D24: ='IDENTITAS PENGHUNI RUMAH 2'!D24 -> 0 | E24: ='IDENTITAS PENGHUNI RUMAH 2'!E24 -> 0
A25: ='IDENTITAS PENGHUNI RUMAH 2'!A25 -> 14 | B25: ='IDENTITAS PENGHUNI RUMAH 2'!B25 -> 0 | C25: ='IDENTITAS PENGHUNI RUMAH 2'!C25 -> 0 | D25: ='IDENTITAS PENGHUNI RUMAH 2'!D25 -> 0 | E25: ='IDENTITAS PENGHUNI RUMAH 2'!E25 -> 0
A26: ='IDENTITAS PENGHUNI RUMAH 2'!A26 -> 15 | B26: ='IDENTITAS PENGHUNI RUMAH 2'!B26 -> 0 | C26: ='IDENTITAS PENGHUNI RUMAH 2'!C26 -> 0 | D26: ='IDENTITAS PENGHUNI RUMAH 2'!D26 -> 0 | E26: ='IDENTITAS PENGHUNI RUMAH 2'!E26 -> 0
A27: ='IDENTITAS PENGHUNI RUMAH 2'!A27 -> 16 | B27: ='IDENTITAS PENGHUNI RUMAH 2'!B27 -> 0 | C27: ='IDENTITAS PENGHUNI RUMAH 2'!C27 -> 0 | D27: ='IDENTITAS PENGHUNI RUMAH 2'!D27 -> 0 | E27: ='IDENTITAS PENGHUNI RUMAH 2'!E27 -> 0
A28: ='IDENTITAS PENGHUNI RUMAH 2'!A28 -> 17 | B28: ='IDENTITAS PENGHUNI RUMAH 2'!B28 -> 0 | C28: ='IDENTITAS PENGHUNI RUMAH 2'!C28 -> 0 | D28: ='IDENTITAS PENGHUNI RUMAH 2'!D28 -> 0 | E28: ='IDENTITAS PENGHUNI RUMAH 2'!E28 -> 0
A29: ='IDENTITAS PENGHUNI RUMAH 2'!A29 -> 18 | B29: ='IDENTITAS PENGHUNI RUMAH 2'!B29 -> 0 | C29: ='IDENTITAS PENGHUNI RUMAH 2'!C29 -> 0 | D29: ='IDENTITAS PENGHUNI RUMAH 2'!D29 -> 0 | E29: ='IDENTITAS PENGHUNI RUMAH 2'!E29 -> 0
A30: ='IDENTITAS PENGHUNI RUMAH 2'!A30 -> 19 | B30: ='IDENTITAS PENGHUNI RUMAH 2'!B30 -> 0 | C30: ='IDENTITAS PENGHUNI RUMAH 2'!C30 -> 0 | D30: ='IDENTITAS PENGHUNI RUMAH 2'!D30 -> 0 | E30: ='IDENTITAS PENGHUNI RUMAH 2'!E30 -> 0
A31: ='IDENTITAS PENGHUNI RUMAH 2'!A31 -> 20 | B31: ='IDENTITAS PENGHUNI RUMAH 2'!B31 -> 0 | C31: ='IDENTITAS PENGHUNI RUMAH 2'!C31 -> 0 | D31: ='IDENTITAS PENGHUNI RUMAH 2'!D31 -> 0 | E31: ='IDENTITAS PENGHUNI RUMAH 2'!E31 -> 0
A32: ='IDENTITAS PENGHUNI RUMAH 2'!A32 -> 21 | B32: ='IDENTITAS PENGHUNI RUMAH 2'!B32 -> 0 | C32: ='IDENTITAS PENGHUNI RUMAH 2'!C32 -> 0 | D32: ='IDENTITAS PENGHUNI RUMAH 2'!D32 -> 0 | E32: ='IDENTITAS PENGHUNI RUMAH 2'!E32 -> 0
... A111: ='IDENTITAS PENGHUNI RUMAH 2'!A111 -> 100 | B111: ='IDENTITAS PENGHUNI RUMAH 2'!B111 -> 0 | C111: ='IDENTITAS PENGHUNI RUMAH 2'!C111 -> 0 | D111: ='IDENTITAS PENGHUNI RUMAH 2'!D111 -> 0 | E111: ='IDENTITAS PENGHUNI RUMAH 2'!E111 -> 0

Sheet KONDISI FISIK RUMAH A
A1: REKAP PENDATAAN RUMAH TIDAK LAYAK HUNI
A3: ='IDENTITAS PENGHUNI RUMAH 1'!A3 -> Provinsi | C3: ='IDENTITAS PENGHUNI RUMAH 1'!C3 -> Sumatera Selatan
A4: ='IDENTITAS PENGHUNI RUMAH 1'!A4 -> Kota | C4: ='IDENTITAS PENGHUNI RUMAH 1'!C4 -> Palembang
A5: ='IDENTITAS PENGHUNI RUMAH 1'!A5 -> Kecamatan | C5: ='IDENTITAS PENGHUNI RUMAH 1'!C5 -> Plaju
A6: ='IDENTITAS PENGHUNI RUMAH 1'!A6 -> Kelurahan | C6: ='IDENTITAS PENGHUNI RUMAH 1'!C6 -> Talang Putri
A7: ='IDENTITAS PENGHUNI RUMAH 1'!A7 -> Tanggal Pendataan | C7: ='IDENTITAS PENGHUNI RUMAH 1'!C7 -> 0
A9: No | B9: Nama Kepala Rumah Tangga | C9: KONDISI FISIK RUMAH
C10: ASPEK KESELAMATAN
C11: NIK | D11: Alamat | E11: RT/RW | F11: Pondasi | G11: Kondisi Kolom dan Balok | H11: Kondisi Konstruksi Atap
A13: ='IDENTITAS PENGHUNI RUMAH 2 (2)'!A12 -> 1 | B13: ='IDENTITAS PENGHUNI RUMAH 2 (2)'!B12 -> Sutamak | C13: ='IDENTITAS PENGHUNI RUMAH 2 (2)'!C12 -> 1671140605720003 | D13: ='IDENTITAS PENGHUNI RUMAH 2 (2)'!D12 -> Lrg. Hikmah II | E13: ='IDENTITAS PENGHUNI RUMAH 2 (2)'!E12 -> RT24 RW06 | F13: Ada | G13: Rusak Sedang/Sebagian | H13: Rusak Sedang/Sebagian
A14: ='IDENTITAS PENGHUNI RUMAH 2 (2)'!A13 -> 2 | B14: ='IDENTITAS PENGHUNI RUMAH 2 (2)'!B13 -> Mawarni | C14: ='IDENTITAS PENGHUNI RUMAH 2 (2)'!C13 -> 1671147006690001 | D14: ='IDENTITAS PENGHUNI RUMAH 2 (2)'!D13 -> Lrg. Hikmah II | E14: ='IDENTITAS PENGHUNI RUMAH 2 (2)'!E13 -> RT 24 / RW 06 | F14: Ada | G14: Rusak Sedang/Sebagian | H14: Rusak Sedang/Sebagian
A15: ='IDENTITAS PENGHUNI RUMAH 2 (2)'!A14 -> 3 | B15: ='IDENTITAS PENGHUNI RUMAH 2 (2)'!B14 -> Samsila | C15: ='IDENTITAS PENGHUNI RUMAH 2 (2)'!C14 -> 1.671145e+15 | D15: ='IDENTITAS PENGHUNI RUMAH 2 (2)'!D14 -> Jl. Kapten Robani Kader | E15: ='IDENTITAS PENGHUNI RUMAH 2 (2)'!E14 -> RT 22 / RW 06 | F15: Ada | G15: Rusak Berat/Seluruhnya | H15: Rusak Berat/Seluruhnya
A16: ='IDENTITAS PENGHUNI RUMAH 2 (2)'!A15 -> 4 | B16: ='IDENTITAS PENGHUNI RUMAH 2 (2)'!B15 -> Sumirah | C16: ='IDENTITAS PENGHUNI RUMAH 2 (2)'!C15 -> 1671146808630004 | D16: ='IDENTITAS PENGHUNI RUMAH 2 (2)'!D15 -> Jl. Kapten Robani Kader | E16: ='IDENTITAS PENGHUNI RUMAH 2 (2)'!E15 -> RT 22 / RW 06 | F16: Ada | G16: Rusak Berat/Seluruhnya | H16: Rusak Berat/Seluruhnya
A17: ='IDENTITAS PENGHUNI RUMAH 2 (2)'!A16 -> 5 | B17: ='IDENTITAS PENGHUNI RUMAH 2 (2)'!B16 -> M. Daud | C17: ='IDENTITAS PENGHUNI RUMAH 2 (2)'!C16 -> 1.6711405e+15 | D17: ='IDENTITAS PENGHUNI RUMAH 2 (2)'!D16 -> Lr. Karya Luhur | E17: ='IDENTITAS PENGHUNI RUMAH 2 (2)'!E16 -> RT 25 RW 06 | F17: Ada | G17: Rusak Berat/Seluruhnya | H17: Rusak Berat/Seluruhnya
A18: ='IDENTITAS PENGHUNI RUMAH 2 (2)'!A17 -> 6 | B18: ='IDENTITAS PENGHUNI RUMAH 2 (2)'!B17 -> Salam Hadi | C18: ='IDENTITAS PENGHUNI RUMAH 2 (2)'!C17 -> 1671141012660005 | D18: ='IDENTITAS PENGHUNI RUMAH 2 (2)'!D17 -> Lrg. Hikmah I | E18: ='IDENTITAS PENGHUNI RUMAH 2 (2)'!E17 -> RT 09 RW 03 | F18: Ada | G18: Rusak Berat/Seluruhnya | H18: Rusak Berat/Seluruhnya
A19: ='IDENTITAS PENGHUNI RUMAH 2 (2)'!A18 -> 7 | B19: ='IDENTITAS PENGHUNI RUMAH 2 (2)'!B18 -> Sukandar | C19: ='IDENTITAS PENGHUNI RUMAH 2 (2)'!C18 -> 1671142101560003 | D19: ='IDENTITAS PENGHUNI RUMAH 2 (2)'!D18 -> Lr. Sidomulyo | E19: ='IDENTITAS PENGHUNI RUMAH 2 (2)'!E18 -> RT12 / RW04 | F19: Ada | G19: Rusak Sedang/Sebagian | H19: Rusak Sedang/Sebagian
A20: ='IDENTITAS PENGHUNI RUMAH 2 (2)'!A19 -> 8 | B20: ='IDENTITAS PENGHUNI RUMAH 2 (2)'!B19 -> Sagiman | C20: ='IDENTITAS PENGHUNI RUMAH 2 (2)'!C19 -> 1671141408520004 | D20: ='IDENTITAS PENGHUNI RUMAH 2 (2)'!D19 -> Lr.Sidokaton II | E20: ='IDENTITAS PENGHUNI RUMAH 2 (2)'!E19 -> RT09 / RW00 | F20: Ada | G20: Rusak Sedang/Sebagian | H20: Rusak Sedang/Sebagian
A21: ='IDENTITAS PENGHUNI RUMAH 2 (2)'!A20 -> 9 | B21: ='IDENTITAS PENGHUNI RUMAH 2 (2)'!B20 -> Daryuni | C21: ='IDENTITAS PENGHUNI RUMAH 2 (2)'!C20 -> 1671145709480003 | D21: ='IDENTITAS PENGHUNI RUMAH 2 (2)'!D20 -> Lr. Karya Luhur | E21: ='IDENTITAS PENGHUNI RUMAH 2 (2)'!E20 -> RT 25 RW 06 | F21: Ada | G21: Rusak Sedang/Sebagian | H21: Rusak Sedang/Sebagian
A22: ='IDENTITAS PENGHUNI RUMAH 2 (2)'!A21 -> 10 | B22: ='IDENTITAS PENGHUNI RUMAH 2 (2)'!B21 -> 0 | C22: ='IDENTITAS PENGHUNI RUMAH 2 (2)'!C21 -> 0 | D22: ='IDENTITAS PENGHUNI RUMAH 2 (2)'!D21 -> 0 | E22: ='IDENTITAS PENGHUNI RUMAH 2 (2)'!E21 -> 0
A23: ='IDENTITAS PENGHUNI RUMAH 2 (2)'!A22 -> 11 | B23: ='IDENTITAS PENGHUNI RUMAH 2 (2)'!B22 -> 0 | C23: ='IDENTITAS PENGHUNI RUMAH 2 (2)'!C22 -> 0 | D23: ='IDENTITAS PENGHUNI RUMAH 2 (2)'!D22 -> 0 | E23: ='IDENTITAS PENGHUNI RUMAH 2 (2)'!E22 -> 0
A24: ='IDENTITAS PENGHUNI RUMAH 2 (2)'!A23 -> 12 | B24: ='IDENTITAS PENGHUNI RUMAH 2 (2)'!B23 -> 0 | C24: ='IDENTITAS PENGHUNI RUMAH 2 (2)'!C23 -> 0 | D24: ='IDENTITAS PENGHUNI RUMAH 2 (2)'!D23 -> 0 | E24: ='IDENTITAS PENGHUNI RUMAH 2 (2)'!E23 -> 0
A25: ='IDENTITAS PENGHUNI RUMAH 2 (2)'!A24 -> 13 | B25: ='IDENTITAS PENGHUNI RUMAH 2 (2)'!B24 -> 0 | C25: ='IDENTITAS PENGHUNI RUMAH 2 (2)'!C24 -> 0 | D25: ='IDENTITAS PENGHUNI RUMAH 2 (2)'!D24 -> 0 | E25: ='IDENTITAS PENGHUNI RUMAH 2 (2)'!E24 -> 0
A26: ='IDENTITAS PENGHUNI RUMAH 2 (2)'!A25 -> 14 | B26: ='IDENTITAS PENGHUNI RUMAH 2 (2)'!B25 -> 0 | C26: ='IDENTITAS PENGHUNI RUMAH 2 (2)'!C25 -> 0 | D26: ='IDENTITAS PENGHUNI RUMAH 2 (2)'!D25 -> 0 | E26: ='IDENTITAS PENGHUNI RUMAH 2 (2)'!E25 -> 0
A27: ='IDENTITAS PENGHUNI RUMAH 2 (2)'!A26 -> 15 | B27: ='IDENTITAS PENGHUNI RUMAH 2 (2)'!B26 -> 0 | C27: ='IDENTITAS PENGHUNI RUMAH 2 (2)'!C26 -> 0 | D27: ='IDENTITAS PENGHUNI RUMAH 2 (2)'!D26 -> 0 | E27: ='IDENTITAS PENGHUNI RUMAH 2 (2)'!E26 -> 0
A28: ='IDENTITAS PENGHUNI RUMAH 2 (2)'!A27 -> 16 | B28: ='IDENTITAS PENGHUNI RUMAH 2 (2)'!B27 -> 0 | C28: ='IDENTITAS PENGHUNI RUMAH 2 (2)'!C27 -> 0 | D28: ='IDENTITAS PENGHUNI RUMAH 2 (2)'!D27 -> 0 | E28: ='IDENTITAS PENGHUNI RUMAH 2 (2)'!E27 -> 0
A29: ='IDENTITAS PENGHUNI RUMAH 2 (2)'!A28 -> 17 | B29: ='IDENTITAS PENGHUNI RUMAH 2 (2)'!B28 -> 0 | C29: ='IDENTITAS PENGHUNI RUMAH 2 (2)'!C28 -> 0 | D29: ='IDENTITAS PENGHUNI RUMAH 2 (2)'!D28 -> 0 | E29: ='IDENTITAS PENGHUNI RUMAH 2 (2)'!E28 -> 0
A30: ='IDENTITAS PENGHUNI RUMAH 2 (2)'!A29 -> 18 | B30: ='IDENTITAS PENGHUNI RUMAH 2 (2)'!B29 -> 0 | C30: ='IDENTITAS PENGHUNI RUMAH 2 (2)'!C29 -> 0 | D30: ='IDENTITAS PENGHUNI RUMAH 2 (2)'!D29 -> 0 | E30: ='IDENTITAS PENGHUNI RUMAH 2 (2)'!E29 -> 0
A31: ='IDENTITAS PENGHUNI RUMAH 2 (2)'!A30 -> 19 | B31: ='IDENTITAS PENGHUNI RUMAH 2 (2)'!B30 -> 0 | C31: ='IDENTITAS PENGHUNI RUMAH 2 (2)'!C30 -> 0 | D31: ='IDENTITAS PENGHUNI RUMAH 2 (2)'!D30 -> 0 | E31: ='IDENTITAS PENGHUNI RUMAH 2 (2)'!E30 -> 0
A32: ='IDENTITAS PENGHUNI RUMAH 2 (2)'!A31 -> 20 | B32: ='IDENTITAS PENGHUNI RUMAH 2 (2)'!B31 -> 0 | C32: ='IDENTITAS PENGHUNI RUMAH 2 (2)'!C31 -> 0 | D32: ='IDENTITAS PENGHUNI RUMAH 2 (2)'!D31 -> 0 | E32: ='IDENTITAS PENGHUNI RUMAH 2 (2)'!E31 -> 0
A33: ='IDENTITAS PENGHUNI RUMAH 2 (2)'!A32 -> 21 | B33: ='IDENTITAS PENGHUNI RUMAH 2 (2)'!B32 -> 0 | C33: ='IDENTITAS PENGHUNI RUMAH 2 (2)'!C32 -> 0 | D33: ='IDENTITAS PENGHUNI RUMAH 2 (2)'!D32 -> 0 | E33: ='IDENTITAS PENGHUNI RUMAH 2 (2)'!E32 -> 0
... A112: ='IDENTITAS PENGHUNI RUMAH 2 (2)'!A111 -> 100 | B112: ='IDENTITAS PENGHUNI RUMAH 2 (2)'!B111 -> 0 | C112: ='IDENTITAS PENGHUNI RUMAH 2 (2)'!C111 -> 0 | D112: ='IDENTITAS PENGHUNI RUMAH 2 (2)'!D111 -> 0 | E112: ='IDENTITAS PENGHUNI RUMAH 2 (2)'!E111 -> 0

Sheet KONDISI FISI RUMAH B
A1: REKAP PENDATAAN RUMAH TIDAK LAYAK HUNI
A3: ='IDENTITAS PENGHUNI RUMAH 1'!A3 -> Provinsi | C3: ='IDENTITAS PENGHUNI RUMAH 1'!C3 -> Sumatera Selatan
A4: ='IDENTITAS PENGHUNI RUMAH 1'!A4 -> Kota | C4: ='IDENTITAS PENGHUNI RUMAH 1'!C4 -> Palembang
A5: ='IDENTITAS PENGHUNI RUMAH 1'!A5 -> Kecamatan | C5: ='IDENTITAS PENGHUNI RUMAH 1'!C5 -> Plaju
A6: ='IDENTITAS PENGHUNI RUMAH 1'!A6 -> Kelurahan | C6: ='IDENTITAS PENGHUNI RUMAH 1'!C6 -> Talang Putri
A7: ='IDENTITAS PENGHUNI RUMAH 1'!A7 -> Tanggal Pendataan | C7: ='IDENTITAS PENGHUNI RUMAH 1'!C7 -> 0
A9: No | B9: Nama Kepala Rumah Tangga | C9: KONDISI FISIK RUMAH
C10: ASPEK KESEHATAN
C11: NIK | D11: Alamat | E11: RT/RW | F11: Jendela/ Lubang Cahaya | G11: Ventilasi | H11: Kepemilikan Kamar Mandi dan Jamban | I11: Jarak Sumber Air Minum ke TPA Tinja
A12: ='IDENTITAS PENGHUNI RUMAH 2 (2)'!A12 -> 1 | B12: ='IDENTITAS PENGHUNI RUMAH 2 (2)'!B12 -> Sutamak | C12: ='IDENTITAS PENGHUNI RUMAH 2 (2)'!C12 -> 1671140605720003 | D12: ='IDENTITAS PENGHUNI RUMAH 2 (2)'!D12 -> Lrg. Hikmah II | E12: ='IDENTITAS PENGHUNI RUMAH 2 (2)'!E12 -> RT24 RW06 | F12: Ada | G12: Ada | H12: Sendiri | I12: Kurang dari 10 Meter
A13: ='IDENTITAS PENGHUNI RUMAH 2 (2)'!A13 -> 2 | B13: ='IDENTITAS PENGHUNI RUMAH 2 (2)'!B13 -> Mawarni | C13: ='IDENTITAS PENGHUNI RUMAH 2 (2)'!C13 -> 1671147006690001 | D13: ='IDENTITAS PENGHUNI RUMAH 2 (2)'!D13 -> Lrg. Hikmah II | E13: ='IDENTITAS PENGHUNI RUMAH 2 (2)'!E13 -> RT 24 / RW 06 | F13: Ada | G13: Tidak Ada | H13: Sendiri | I13: Kurang dari 10 Meter
A14: ='IDENTITAS PENGHUNI RUMAH 2 (2)'!A14 -> 3 | B14: ='IDENTITAS PENGHUNI RUMAH 2 (2)'!B14 -> Samsila | C14: ='IDENTITAS PENGHUNI RUMAH 2 (2)'!C14 -> 1.671145e+15 | D14: ='IDENTITAS PENGHUNI RUMAH 2 (2)'!D14 -> Jl. Kapten Robani Kader | E14: ='IDENTITAS PENGHUNI RUMAH 2 (2)'!E14 -> RT 22 / RW 06 | F14: Ada | G14: Ada | H14: Sendiri | I14: Kurang dari 10 Meter
A15: ='IDENTITAS PENGHUNI RUMAH 2 (2)'!A15 -> 4 | B15: ='IDENTITAS PENGHUNI RUMAH 2 (2)'!B15 -> Sumirah | C15: ='IDENTITAS PENGHUNI RUMAH 2 (2)'!C15 -> 1671146808630004 | D15: ='IDENTITAS PENGHUNI RUMAH 2 (2)'!D15 -> Jl. Kapten Robani Kader | E15: ='IDENTITAS PENGHUNI RUMAH 2 (2)'!E15 -> RT 22 / RW 06 | F15: Ada | G15: Tidak Ada | H15: Sendiri | I15: Kurang dari 10 Meter
A16: ='IDENTITAS PENGHUNI RUMAH 2 (2)'!A16 -> 5 | B16: ='IDENTITAS PENGHUNI RUMAH 2 (2)'!B16 -> M. Daud | C16: ='IDENTITAS PENGHUNI RUMAH 2 (2)'!C16 -> 1.6711405e+15 | D16: ='IDENTITAS PENGHUNI RUMAH 2 (2)'!D16 -> Lr. Karya Luhur | E16: ='IDENTITAS PENGHUNI RUMAH 2 (2)'!E16 -> RT 25 RW 06 | F16: Ada | G16: Tidak Ada | H16: Bersama/MCK Komunal | I16: Kurang dari 10 Meter
A17: ='IDENTITAS PENGHUNI RUMAH 2 (2)'!A17 -> 6 | B17: ='IDENTITAS PENGHUNI RUMAH 2 (2)'!B17 -> Salam Hadi | C17: ='IDENTITAS PENGHUNI RUMAH 2 (2)'!C17 -> 1671141012660005 | D17: ='IDENTITAS PENGHUNI RUMAH 2 (2)'!D17 -> Lrg. Hikmah I | E17: ='IDENTITAS PENGHUNI RUMAH 2 (2)'!E17 -> RT 09 RW 03 | F17: Ada | G17: Tidak Ada | H17: Sendiri | I17: Kurang dari 10 Meter
A18: ='IDENTITAS PENGHUNI RUMAH 2 (2)'!A18 -> 7 | B18: ='IDENTITAS PENGHUNI RUMAH 2 (2)'!B18 -> Sukandar | C18: ='IDENTITAS PENGHUNI RUMAH 2 (2)'!C18 -> 1671142101560003 | D18: ='IDENTITAS PENGHUNI RUMAH 2 (2)'!D18 -> Lr. Sidomulyo | E18: ='IDENTITAS PENGHUNI RUMAH 2 (2)'!E18 -> RT12 / RW04 | F18: Ada | G18: Tidak Ada | H18: Sendiri | I18: Kurang dari 10 Meter
A19: ='IDENTITAS PENGHUNI RUMAH 2 (2)'!A19 -> 8 | B19: ='IDENTITAS PENGHUNI RUMAH 2 (2)'!B19 -> Sagiman | C19: ='IDENTITAS PENGHUNI RUMAH 2 (2)'!C19 -> 1671141408520004 | D19: ='IDENTITAS PENGHUNI RUMAH 2 (2)'!D19 -> Lr.Sidokaton II | E19: ='IDENTITAS PENGHUNI RUMAH 2 (2)'!E19 -> RT09 / RW00 | F19: Ada | G19: Tidak Ada | H19: Sendiri | I19: Kurang dari 10 Meter
A20: ='IDENTITAS PENGHUNI RUMAH 2 (2)'!A20 -> 9 | B20: ='IDENTITAS PENGHUNI RUMAH 2 (2)'!B20 -> Daryuni | C20: ='IDENTITAS PENGHUNI RUMAH 2 (2)'!C20 -> 1671145709480003 | D20: ='IDENTITAS PENGHUNI RUMAH 2 (2)'!D20 -> Lr. Karya Luhur | E20: ='IDENTITAS PENGHUNI RUMAH 2 (2)'!E20 -> RT 25 RW 06 | F20: Ada | G20: Tidak Ada | H20: Sendiri | I20: Kurang dari 10 Meter
A21: ='IDENTITAS PENGHUNI RUMAH 2 (2)'!A21 -> 10 | B21: ='IDENTITAS PENGHUNI RUMAH 2 (2)'!B21 -> 0 | C21: ='IDENTITAS PENGHUNI RUMAH 2 (2)'!C21 -> 0 | D21: ='IDENTITAS PENGHUNI RUMAH 2 (2)'!D21 -> 0 | E21: ='IDENTITAS PENGHUNI RUMAH 2 (2)'!E21 -> 0
A22: ='IDENTITAS PENGHUNI RUMAH 2 (2)'!A22 -> 11 | B22: ='IDENTITAS PENGHUNI RUMAH 2 (2)'!B22 -> 0 | C22: ='IDENTITAS PENGHUNI RUMAH 2 (2)'!C22 -> 0 | D22: ='IDENTITAS PENGHUNI RUMAH 2 (2)'!D22 -> 0 | E22: ='IDENTITAS PENGHUNI RUMAH 2 (2)'!E22 -> 0
A23: ='IDENTITAS PENGHUNI RUMAH 2 (2)'!A23 -> 12 | B23: ='IDENTITAS PENGHUNI RUMAH 2 (2)'!B23 -> 0 | C23: ='IDENTITAS PENGHUNI RUMAH 2 (2)'!C23 -> 0 | D23: ='IDENTITAS PENGHUNI RUMAH 2 (2)'!D23 -> 0 | E23: ='IDENTITAS PENGHUNI RUMAH 2 (2)'!E23 -> 0
A24: ='IDENTITAS PENGHUNI RUMAH 2 (2)'!A24 -> 13 | B24: ='IDENTITAS PENGHUNI RUMAH 2 (2)'!B24 -> 0 | C24: ='IDENTITAS PENGHUNI RUMAH 2 (2)'!C24 -> 0 | D24: ='IDENTITAS PENGHUNI RUMAH 2 (2)'!D24 -> 0 | E24: ='IDENTITAS PENGHUNI RUMAH 2 (2)'!E24 -> 0
A25: ='IDENTITAS PENGHUNI RUMAH 2 (2)'!A25 -> 14 | B25: ='IDENTITAS PENGHUNI RUMAH 2 (2)'!B25 -> 0 | C25: ='IDENTITAS PENGHUNI RUMAH 2 (2)'!C25 -> 0 | D25: ='IDENTITAS PENGHUNI RUMAH 2 (2)'!D25 -> 0 | E25: ='IDENTITAS PENGHUNI RUMAH 2 (2)'!E25 -> 0
A26: ='IDENTITAS PENGHUNI RUMAH 2 (2)'!A26 -> 15 | B26: ='IDENTITAS PENGHUNI RUMAH 2 (2)'!B26 -> 0 | C26: ='IDENTITAS PENGHUNI RUMAH 2 (2)'!C26 -> 0 | D26: ='IDENTITAS PENGHUNI RUMAH 2 (2)'!D26 -> 0 | E26: ='IDENTITAS PENGHUNI RUMAH 2 (2)'!E26 -> 0
A27: ='IDENTITAS PENGHUNI RUMAH 2 (2)'!A27 -> 16 | B27: ='IDENTITAS PENGHUNI RUMAH 2 (2)'!B27 -> 0 | C27: ='IDENTITAS PENGHUNI RUMAH 2 (2)'!C27 -> 0 | D27: ='IDENTITAS PENGHUNI RUMAH 2 (2)'!D27 -> 0 | E27: ='IDENTITAS PENGHUNI RUMAH 2 (2)'!E27 -> 0
A28: ='IDENTITAS PENGHUNI RUMAH 2 (2)'!A28 -> 17 | B28: ='IDENTITAS PENGHUNI RUMAH 2 (2)'!B28 -> 0 | C28: ='IDENTITAS PENGHUNI RUMAH 2 (2)'!C28 -> 0 | D28: ='IDENTITAS PENGHUNI RUMAH 2 (2)'!D28 -> 0 | E28: ='IDENTITAS PENGHUNI RUMAH 2 (2)'!E28 -> 0
A29: ='IDENTITAS PENGHUNI RUMAH 2 (2)'!A29 -> 18 | B29: ='IDENTITAS PENGHUNI RUMAH 2 (2)'!B29 -> 0 | C29: ='IDENTITAS PENGHUNI RUMAH 2 (2)'!C29 -> 0 | D29: ='IDENTITAS PENGHUNI RUMAH 2 (2)'!D29 -> 0 | E29: ='IDENTITAS PENGHUNI RUMAH 2 (2)'!E29 -> 0
A30: ='IDENTITAS PENGHUNI RUMAH 2 (2)'!A30 -> 19 | B30: ='IDENTITAS PENGHUNI RUMAH 2 (2)'!B30 -> 0 | C30: ='IDENTITAS PENGHUNI RUMAH 2 (2)'!C30 -> 0 | D30: ='IDENTITAS PENGHUNI RUMAH 2 (2)'!D30 -> 0 | E30: ='IDENTITAS PENGHUNI RUMAH 2 (2)'!E30 -> 0
A31: ='IDENTITAS PENGHUNI RUMAH 2 (2)'!A31 -> 20 | B31: ='IDENTITAS PENGHUNI RUMAH 2 (2)'!B31 -> 0 | C31: ='IDENTITAS PENGHUNI RUMAH 2 (2)'!C31 -> 0 | D31: ='IDENTITAS PENGHUNI RUMAH 2 (2)'!D31 -> 0 | E31: ='IDENTITAS PENGHUNI RUMAH 2 (2)'!E31 -> 0
A32: ='IDENTITAS PENGHUNI RUMAH 2 (2)'!A32 -> 21 | B32: ='IDENTITAS PENGHUNI RUMAH 2 (2)'!B32 -> 0 | C32: ='IDENTITAS PENGHUNI RUMAH 2 (2)'!C32 -> 0 | D32: ='IDENTITAS PENGHUNI RUMAH 2 (2)'!D32 -> 0 | E32: ='IDENTITAS PENGHUNI RUMAH 2 (2)'!E32 -> 0
... A111: ='IDENTITAS PENGHUNI RUMAH 2 (2)'!A111 -> 100 | B111: ='IDENTITAS PENGHUNI RUMAH 2 (2)'!B111 -> 0 | C111: ='IDENTITAS PENGHUNI RUMAH 2 (2)'!C111 -> 0 | D111: ='IDENTITAS PENGHUNI RUMAH 2 (2)'!D111 -> 0 | E111: ='IDENTITAS PENGHUNI RUMAH 2 (2)'!E111 -> 0

Sheet KONDISI FISI RUMAH C
A1: REKAP PENDATAAN RUMAH TIDAK LAYAK HUNI
A3: ='IDENTITAS PENGHUNI RUMAH 1'!A3 -> Provinsi | C3: ='IDENTITAS PENGHUNI RUMAH 1'!C3 -> Sumatera Selatan
A4: ='IDENTITAS PENGHUNI RUMAH 1'!A4 -> Kota | C4: ='IDENTITAS PENGHUNI RUMAH 1'!C4 -> Palembang
A5: ='IDENTITAS PENGHUNI RUMAH 1'!A5 -> Kecamatan | C5: ='IDENTITAS PENGHUNI RUMAH 1'!C5 -> Plaju
A6: ='IDENTITAS PENGHUNI RUMAH 1'!A6 -> Kelurahan | C6: ='IDENTITAS PENGHUNI RUMAH 1'!C6 -> Talang Putri
A7: ='IDENTITAS PENGHUNI RUMAH 1'!A7 -> Tanggal Pendataan | C7: ='IDENTITAS PENGHUNI RUMAH 1'!C7 -> 0
A9: No | B9: Nama Kepala Rumah Tangga | C9: KONDISI FISIK RUMAH
C10: ASPEK PERSYARATAN LUAS DAN KEBUTUHAN RUANG
C11: NIK | D11: Alamat | E11: RT/RW | F11: Luas Rumah M2 | G11: Jumlah Peghuni (Orang)
A13: ='IDENTITAS PENGHUNI RUMAH 2 (2)'!A12 -> 1 | B13: ='IDENTITAS PENGHUNI RUMAH 2 (2)'!B12 -> Sutamak | C13: ='IDENTITAS PENGHUNI RUMAH 2 (2)'!C12 -> 1671140605720003 | D13: ='IDENTITAS PENGHUNI RUMAH 2 (2)'!D12 -> Lrg. Hikmah II | E13: ='IDENTITAS PENGHUNI RUMAH 2 (2)'!E12 -> RT24 RW06 | F13: 30 | G13: 8
A14: ='IDENTITAS PENGHUNI RUMAH 2 (2)'!A13 -> 2 | B14: ='IDENTITAS PENGHUNI RUMAH 2 (2)'!B13 -> Mawarni | C14: ='IDENTITAS PENGHUNI RUMAH 2 (2)'!C13 -> 1671147006690001 | D14: ='IDENTITAS PENGHUNI RUMAH 2 (2)'!D13 -> Lrg. Hikmah II | E14: ='IDENTITAS PENGHUNI RUMAH 2 (2)'!E13 -> RT 24 / RW 06 | F14: 18 | G14: 1
A15: ='IDENTITAS PENGHUNI RUMAH 2 (2)'!A14 -> 3 | B15: ='IDENTITAS PENGHUNI RUMAH 2 (2)'!B14 -> Samsila | C15: ='IDENTITAS PENGHUNI RUMAH 2 (2)'!C14 -> 1.671145e+15 | D15: ='IDENTITAS PENGHUNI RUMAH 2 (2)'!D14 -> Jl. Kapten Robani Kader | E15: ='IDENTITAS PENGHUNI RUMAH 2 (2)'!E14 -> RT 22 / RW 06 | F15: 48 | G15: 1
A16: ='IDENTITAS PENGHUNI RUMAH 2 (2)'!A15 -> 4 | B16: ='IDENTITAS PENGHUNI RUMAH 2 (2)'!B15 -> Sumirah | C16: ='IDENTITAS PENGHUNI RUMAH 2 (2)'!C15 -> 1671146808630004 | D16: ='IDENTITAS PENGHUNI RUMAH 2 (2)'!D15 -> Jl. Kapten Robani Kader | E16: ='IDENTITAS PENGHUNI RUMAH 2 (2)'!E15 -> RT 22 / RW 06 | F16: 12 | G16: 1
A17: ='IDENTITAS PENGHUNI RUMAH 2 (2)'!A16 -> 5 | B17: ='IDENTITAS PENGHUNI RUMAH 2 (2)'!B16 -> M. Daud | C17: ='IDENTITAS PENGHUNI RUMAH 2 (2)'!C16 -> 1.6711405e+15 | D17: ='IDENTITAS PENGHUNI RUMAH 2 (2)'!D16 -> Lr. Karya Luhur | E17: ='IDENTITAS PENGHUNI RUMAH 2 (2)'!E16 -> RT 25 RW 06 | F17: 36 | G17: 6
A18: ='IDENTITAS PENGHUNI RUMAH 2 (2)'!A17 -> 6 | B18: ='IDENTITAS PENGHUNI RUMAH 2 (2)'!B17 -> Salam Hadi | C18: ='IDENTITAS PENGHUNI RUMAH 2 (2)'!C17 -> 1671141012660005 | D18: ='IDENTITAS PENGHUNI RUMAH 2 (2)'!D17 -> Lrg. Hikmah I | E18: ='IDENTITAS PENGHUNI RUMAH 2 (2)'!E17 -> RT 09 RW 03 | F18: 30 | G18: 1
A19: ='IDENTITAS PENGHUNI RUMAH 2 (2)'!A18 -> 7 | B19: ='IDENTITAS PENGHUNI RUMAH 2 (2)'!B18 -> Sukandar | C19: ='IDENTITAS PENGHUNI RUMAH 2 (2)'!C18 -> 1671142101560003 | D19: ='IDENTITAS PENGHUNI RUMAH 2 (2)'!D18 -> Lr. Sidomulyo | E19: ='IDENTITAS PENGHUNI RUMAH 2 (2)'!E18 -> RT12 / RW04 | F19: 30 | G19: 1
A20: ='IDENTITAS PENGHUNI RUMAH 2 (2)'!A19 -> 8 | B20: ='IDENTITAS PENGHUNI RUMAH 2 (2)'!B19 -> Sagiman | C20: ='IDENTITAS PENGHUNI RUMAH 2 (2)'!C19 -> 1671141408520004 | D20: ='IDENTITAS PENGHUNI RUMAH 2 (2)'!D19 -> Lr.Sidokaton II | E20: ='IDENTITAS PENGHUNI RUMAH 2 (2)'!E19 -> RT09 / RW00 | F20: 20 | G20: 1
A21: ='IDENTITAS PENGHUNI RUMAH 2 (2)'!A20 -> 9 | B21: ='IDENTITAS PENGHUNI RUMAH 2 (2)'!B20 -> Daryuni | C21: ='IDENTITAS PENGHUNI RUMAH 2 (2)'!C20 -> 1671145709480003 | D21: ='IDENTITAS PENGHUNI RUMAH 2 (2)'!D20 -> Lr. Karya Luhur | E21: ='IDENTITAS PENGHUNI RUMAH 2 (2)'!E20 -> RT 25 RW 06 | F21: 24 | G21: 5
A22: ='IDENTITAS PENGHUNI RUMAH 2 (2)'!A21 -> 10 | B22: ='IDENTITAS PENGHUNI RUMAH 2 (2)'!B21 -> 0 | C22: ='IDENTITAS PENGHUNI RUMAH 2 (2)'!C21 -> 0 | D22: ='IDENTITAS PENGHUNI RUMAH 2 (2)'!D21 -> 0 | E22: ='IDENTITAS PENGHUNI RUMAH 2 (2)'!E21 -> 0
A23: ='IDENTITAS PENGHUNI RUMAH 2 (2)'!A22 -> 11 | B23: ='IDENTITAS PENGHUNI RUMAH 2 (2)'!B22 -> 0 | C23: ='IDENTITAS PENGHUNI RUMAH 2 (2)'!C22 -> 0 | D23: ='IDENTITAS PENGHUNI RUMAH 2 (2)'!D22 -> 0 | E23: ='IDENTITAS PENGHUNI RUMAH 2 (2)'!E22 -> 0
A24: ='IDENTITAS PENGHUNI RUMAH 2 (2)'!A23 -> 12 | B24: ='IDENTITAS PENGHUNI RUMAH 2 (2)'!B23 -> 0 | C24: ='IDENTITAS PENGHUNI RUMAH 2 (2)'!C23 -> 0 | D24: ='IDENTITAS PENGHUNI RUMAH 2 (2)'!D23 -> 0 | E24: ='IDENTITAS PENGHUNI RUMAH 2 (2)'!E23 -> 0
A25: ='IDENTITAS PENGHUNI RUMAH 2 (2)'!A24 -> 13 | B25: ='IDENTITAS PENGHUNI RUMAH 2 (2)'!B24 -> 0 | C25: ='IDENTITAS PENGHUNI RUMAH 2 (2)'!C24 -> 0 | D25: ='IDENTITAS PENGHUNI RUMAH 2 (2)'!D24 -> 0 | E25: ='IDENTITAS PENGHUNI RUMAH 2 (2)'!E24 -> 0
A26: ='IDENTITAS PENGHUNI RUMAH 2 (2)'!A25 -> 14 | B26: ='IDENTITAS PENGHUNI RUMAH 2 (2)'!B25 -> 0 | C26: ='IDENTITAS PENGHUNI RUMAH 2 (2)'!C25 -> 0 | D26: ='IDENTITAS PENGHUNI RUMAH 2 (2)'!D25 -> 0 | E26: ='IDENTITAS PENGHUNI RUMAH 2 (2)'!E25 -> 0
A27: ='IDENTITAS PENGHUNI RUMAH 2 (2)'!A26 -> 15 | B27: ='IDENTITAS PENGHUNI RUMAH 2 (2)'!B26 -> 0 | C27: ='IDENTITAS PENGHUNI RUMAH 2 (2)'!C26 -> 0 | D27: ='IDENTITAS PENGHUNI RUMAH 2 (2)'!D26 -> 0 | E27: ='IDENTITAS PENGHUNI RUMAH 2 (2)'!E26 -> 0
A28: ='IDENTITAS PENGHUNI RUMAH 2 (2)'!A27 -> 16 | B28: ='IDENTITAS PENGHUNI RUMAH 2 (2)'!B27 -> 0 | C28: ='IDENTITAS PENGHUNI RUMAH 2 (2)'!C27 -> 0 | D28: ='IDENTITAS PENGHUNI RUMAH 2 (2)'!D27 -> 0 | E28: ='IDENTITAS PENGHUNI RUMAH 2 (2)'!E27 -> 0
A29: ='IDENTITAS PENGHUNI RUMAH 2 (2)'!A28 -> 17 | B29: ='IDENTITAS PENGHUNI RUMAH 2 (2)'!B28 -> 0 | C29: ='IDENTITAS PENGHUNI RUMAH 2 (2)'!C28 -> 0 | D29: ='IDENTITAS PENGHUNI RUMAH 2 (2)'!D28 -> 0 | E29: ='IDENTITAS PENGHUNI RUMAH 2 (2)'!E28 -> 0
A30: ='IDENTITAS PENGHUNI RUMAH 2 (2)'!A29 -> 18 | B30: ='IDENTITAS PENGHUNI RUMAH 2 (2)'!B29 -> 0 | C30: ='IDENTITAS PENGHUNI RUMAH 2 (2)'!C29 -> 0 | D30: ='IDENTITAS PENGHUNI RUMAH 2 (2)'!D29 -> 0 | E30: ='IDENTITAS PENGHUNI RUMAH 2 (2)'!E29 -> 0
A31: ='IDENTITAS PENGHUNI RUMAH 2 (2)'!A30 -> 19 | B31: ='IDENTITAS PENGHUNI RUMAH 2 (2)'!B30 -> 0 | C31: ='IDENTITAS PENGHUNI RUMAH 2 (2)'!C30 -> 0 | D31: ='IDENTITAS PENGHUNI RUMAH 2 (2)'!D30 -> 0 | E31: ='IDENTITAS PENGHUNI RUMAH 2 (2)'!E30 -> 0
A32: ='IDENTITAS PENGHUNI RUMAH 2 (2)'!A31 -> 20 | B32: ='IDENTITAS PENGHUNI RUMAH 2 (2)'!B31 -> 0 | C32: ='IDENTITAS PENGHUNI RUMAH 2 (2)'!C31 -> 0 | D32: ='IDENTITAS PENGHUNI RUMAH 2 (2)'!D31 -> 0 | E32: ='IDENTITAS PENGHUNI RUMAH 2 (2)'!E31 -> 0
A33: ='IDENTITAS PENGHUNI RUMAH 2 (2)'!A32 -> 21 | B33: ='IDENTITAS PENGHUNI RUMAH 2 (2)'!B32 -> 0 | C33: ='IDENTITAS PENGHUNI RUMAH 2 (2)'!C32 -> 0 | D33: ='IDENTITAS PENGHUNI RUMAH 2 (2)'!D32 -> 0 | E33: ='IDENTITAS PENGHUNI RUMAH 2 (2)'!E32 -> 0
... A112: ='IDENTITAS PENGHUNI RUMAH 2 (2)'!A111 -> 100 | B112: ='IDENTITAS PENGHUNI RUMAH 2 (2)'!B111 -> 0 | C112: ='IDENTITAS PENGHUNI RUMAH 2 (2)'!C111 -> 0 | D112: ='IDENTITAS PENGHUNI RUMAH 2 (2)'!D111 -> 0 | E112: ='IDENTITAS PENGHUNI RUMAH 2 (2)'!E111 -> 0

Sheet KONDISI FISI RUMAH D.1
A1: REKAP PENDATAAN RUMAH TIDAK LAYAK HUNI
A3: ='IDENTITAS PENGHUNI RUMAH 1'!A3 -> Provinsi | C3: ='IDENTITAS PENGHUNI RUMAH 1'!C3 -> Sumatera Selatan
A4: ='IDENTITAS PENGHUNI RUMAH 1'!A4 -> Kota | C4: ='IDENTITAS PENGHUNI RUMAH 1'!C4 -> Palembang
A5: ='IDENTITAS PENGHUNI RUMAH 1'!A5 -> Kecamatan | C5: ='IDENTITAS PENGHUNI RUMAH 1'!C5 -> Plaju
A6: ='IDENTITAS PENGHUNI RUMAH 1'!A6 -> Kelurahan | C6: ='IDENTITAS PENGHUNI RUMAH 1'!C6 -> Talang Putri
A7: ='IDENTITAS PENGHUNI RUMAH 1'!A7 -> Tanggal Pendataan | C7: ='IDENTITAS PENGHUNI RUMAH 1'!C7 -> 0
A9: No | B9: Nama Kepala Rumah Tangga | C9: KONDISI FISIK RUMAH
C10: ASPEK KOMPONEN BAHAN BANGUNAN SESUAI KONTEKS LOKAL
C11: NIK | D11: Alamat | E11: RT/RW | F11: Material Atap Terluas | G11: Kondisi Atap
A13: ='IDENTITAS PENGHUNI RUMAH 2 (2)'!A12 -> 1 | B13: ='IDENTITAS PENGHUNI RUMAH 2 (2)'!B12 -> Sutamak | C13: ='IDENTITAS PENGHUNI RUMAH 2 (2)'!C12 -> 1671140605720003 | D13: ='IDENTITAS PENGHUNI RUMAH 2 (2)'!D12 -> Lrg. Hikmah II | E13: ='IDENTITAS PENGHUNI RUMAH 2 (2)'!E12 -> RT24 RW06 | F13: Seng | G13: Rusak Berat/Seluruhnya
A14: ='IDENTITAS PENGHUNI RUMAH 2 (2)'!A13 -> 2 | B14: ='IDENTITAS PENGHUNI RUMAH 2 (2)'!B13 -> Mawarni | C14: ='IDENTITAS PENGHUNI RUMAH 2 (2)'!C13 -> 1671147006690001 | D14: ='IDENTITAS PENGHUNI RUMAH 2 (2)'!D13 -> Lrg. Hikmah II | E14: ='IDENTITAS PENGHUNI RUMAH 2 (2)'!E13 -> RT 24 / RW 06 | F14: Seng | G14: Rusak Berat/Seluruhnya
A15: ='IDENTITAS PENGHUNI RUMAH 2 (2)'!A14 -> 3 | B15: ='IDENTITAS PENGHUNI RUMAH 2 (2)'!B14 -> Samsila | C15: ='IDENTITAS PENGHUNI RUMAH 2 (2)'!C14 -> 1.671145e+15 | D15: ='IDENTITAS PENGHUNI RUMAH 2 (2)'!D14 -> Jl. Kapten Robani Kader | E15: ='IDENTITAS PENGHUNI RUMAH 2 (2)'!E14 -> RT 22 / RW 06 | F15: Seng | G15: Rusak Sedang/Sebagian
A16: ='IDENTITAS PENGHUNI RUMAH 2 (2)'!A15 -> 4 | B16: ='IDENTITAS PENGHUNI RUMAH 2 (2)'!B15 -> Sumirah | C16: ='IDENTITAS PENGHUNI RUMAH 2 (2)'!C15 -> 1671146808630004 | D16: ='IDENTITAS PENGHUNI RUMAH 2 (2)'!D15 -> Jl. Kapten Robani Kader | E16: ='IDENTITAS PENGHUNI RUMAH 2 (2)'!E15 -> RT 22 / RW 06 | F16: Seng | G16: Rusak Berat/Seluruhnya
A17: ='IDENTITAS PENGHUNI RUMAH 2 (2)'!A16 -> 5 | B17: ='IDENTITAS PENGHUNI RUMAH 2 (2)'!B16 -> M. Daud | C17: ='IDENTITAS PENGHUNI RUMAH 2 (2)'!C16 -> 1.6711405e+15 | D17: ='IDENTITAS PENGHUNI RUMAH 2 (2)'!D16 -> Lr. Karya Luhur | E17: ='IDENTITAS PENGHUNI RUMAH 2 (2)'!E16 -> RT 25 RW 06 | F17: Genteng | G17: Rusak Sedang/Sebagian
A18: ='IDENTITAS PENGHUNI RUMAH 2 (2)'!A17 -> 6 | B18: ='IDENTITAS PENGHUNI RUMAH 2 (2)'!B17 -> Salam Hadi | C18: ='IDENTITAS PENGHUNI RUMAH 2 (2)'!C17 -> 1671141012660005 | D18: ='IDENTITAS PENGHUNI RUMAH 2 (2)'!D17 -> Lrg. Hikmah I | E18: ='IDENTITAS PENGHUNI RUMAH 2 (2)'!E17 -> RT 09 RW 03 | F18: Seng | G18: Rusak Sedang/Sebagian
A19: ='IDENTITAS PENGHUNI RUMAH 2 (2)'!A18 -> 7 | B19: ='IDENTITAS PENGHUNI RUMAH 2 (2)'!B18 -> Sukandar | C19: ='IDENTITAS PENGHUNI RUMAH 2 (2)'!C18 -> 1671142101560003 | D19: ='IDENTITAS PENGHUNI RUMAH 2 (2)'!D18 -> Lr. Sidomulyo | E19: ='IDENTITAS PENGHUNI RUMAH 2 (2)'!E18 -> RT12 / RW04 | F19: Seng | G19: Rusak Sedang/Sebagian
A20: ='IDENTITAS PENGHUNI RUMAH 2 (2)'!A19 -> 8 | B20: ='IDENTITAS PENGHUNI RUMAH 2 (2)'!B19 -> Sagiman | C20: ='IDENTITAS PENGHUNI RUMAH 2 (2)'!C19 -> 1671141408520004 | D20: ='IDENTITAS PENGHUNI RUMAH 2 (2)'!D19 -> Lr.Sidokaton II | E20: ='IDENTITAS PENGHUNI RUMAH 2 (2)'!E19 -> RT09 / RW00 | F20: Seng | G20: Rusak Sedang/Sebagian
A21: ='IDENTITAS PENGHUNI RUMAH 2 (2)'!A20 -> 9 | B21: ='IDENTITAS PENGHUNI RUMAH 2 (2)'!B20 -> Daryuni | C21: ='IDENTITAS PENGHUNI RUMAH 2 (2)'!C20 -> 1671145709480003 | D21: ='IDENTITAS PENGHUNI RUMAH 2 (2)'!D20 -> Lr. Karya Luhur | E21: ='IDENTITAS PENGHUNI RUMAH 2 (2)'!E20 -> RT 25 RW 06 | F21: Genteng | G21: Rusak Sedang/Sebagian
A22: ='IDENTITAS PENGHUNI RUMAH 2 (2)'!A21 -> 10 | B22: ='IDENTITAS PENGHUNI RUMAH 2 (2)'!B21 -> 0 | C22: ='IDENTITAS PENGHUNI RUMAH 2 (2)'!C21 -> 0 | D22: ='IDENTITAS PENGHUNI RUMAH 2 (2)'!D21 -> 0 | E22: ='IDENTITAS PENGHUNI RUMAH 2 (2)'!E21 -> 0
A23: ='IDENTITAS PENGHUNI RUMAH 2 (2)'!A22 -> 11 | B23: ='IDENTITAS PENGHUNI RUMAH 2 (2)'!B22 -> 0 | C23: ='IDENTITAS PENGHUNI RUMAH 2 (2)'!C22 -> 0 | D23: ='IDENTITAS PENGHUNI RUMAH 2 (2)'!D22 -> 0 | E23: ='IDENTITAS PENGHUNI RUMAH 2 (2)'!E22 -> 0
A24: ='IDENTITAS PENGHUNI RUMAH 2 (2)'!A23 -> 12 | B24: ='IDENTITAS PENGHUNI RUMAH 2 (2)'!B23 -> 0 | C24: ='IDENTITAS PENGHUNI RUMAH 2 (2)'!C23 -> 0 | D24: ='IDENTITAS PENGHUNI RUMAH 2 (2)'!D23 -> 0 | E24: ='IDENTITAS PENGHUNI RUMAH 2 (2)'!E23 -> 0
A25: ='IDENTITAS PENGHUNI RUMAH 2 (2)'!A24 -> 13 | B25: ='IDENTITAS PENGHUNI RUMAH 2 (2)'!B24 -> 0 | C25: ='IDENTITAS PENGHUNI RUMAH 2 (2)'!C24 -> 0 | D25: ='IDENTITAS PENGHUNI RUMAH 2 (2)'!D24 -> 0 | E25: ='IDENTITAS PENGHUNI RUMAH 2 (2)'!E24 -> 0
A26: ='IDENTITAS PENGHUNI RUMAH 2 (2)'!A25 -> 14 | B26: ='IDENTITAS PENGHUNI RUMAH 2 (2)'!B25 -> 0 | C26: ='IDENTITAS PENGHUNI RUMAH 2 (2)'!C25 -> 0 | D26: ='IDENTITAS PENGHUNI RUMAH 2 (2)'!D25 -> 0 | E26: ='IDENTITAS PENGHUNI RUMAH 2 (2)'!E25 -> 0
A27: ='IDENTITAS PENGHUNI RUMAH 2 (2)'!A26 -> 15 | B27: ='IDENTITAS PENGHUNI RUMAH 2 (2)'!B26 -> 0 | C27: ='IDENTITAS PENGHUNI RUMAH 2 (2)'!C26 -> 0 | D27: ='IDENTITAS PENGHUNI RUMAH 2 (2)'!D26 -> 0 | E27: ='IDENTITAS PENGHUNI RUMAH 2 (2)'!E26 -> 0
A28: ='IDENTITAS PENGHUNI RUMAH 2 (2)'!A27 -> 16 | B28: ='IDENTITAS PENGHUNI RUMAH 2 (2)'!B27 -> 0 | C28: ='IDENTITAS PENGHUNI RUMAH 2 (2)'!C27 -> 0 | D28: ='IDENTITAS PENGHUNI RUMAH 2 (2)'!D27 -> 0 | E28: ='IDENTITAS PENGHUNI RUMAH 2 (2)'!E27 -> 0
A29: ='IDENTITAS PENGHUNI RUMAH 2 (2)'!A28 -> 17 | B29: ='IDENTITAS PENGHUNI RUMAH 2 (2)'!B28 -> 0 | C29: ='IDENTITAS PENGHUNI RUMAH 2 (2)'!C28 -> 0 | D29: ='IDENTITAS PENGHUNI RUMAH 2 (2)'!D28 -> 0 | E29: ='IDENTITAS PENGHUNI RUMAH 2 (2)'!E28 -> 0
A30: ='IDENTITAS PENGHUNI RUMAH 2 (2)'!A29 -> 18 | B30: ='IDENTITAS PENGHUNI RUMAH 2 (2)'!B29 -> 0 | C30: ='IDENTITAS PENGHUNI RUMAH 2 (2)'!C29 -> 0 | D30: ='IDENTITAS PENGHUNI RUMAH 2 (2)'!D29 -> 0 | E30: ='IDENTITAS PENGHUNI RUMAH 2 (2)'!E29 -> 0
A31: ='IDENTITAS PENGHUNI RUMAH 2 (2)'!A30 -> 19 | B31: ='IDENTITAS PENGHUNI RUMAH 2 (2)'!B30 -> 0 | C31: ='IDENTITAS PENGHUNI RUMAH 2 (2)'!C30 -> 0 | D31: ='IDENTITAS PENGHUNI RUMAH 2 (2)'!D30 -> 0 | E31: ='IDENTITAS PENGHUNI RUMAH 2 (2)'!E30 -> 0
A32: ='IDENTITAS PENGHUNI RUMAH 2 (2)'!A31 -> 20 | B32: ='IDENTITAS PENGHUNI RUMAH 2 (2)'!B31 -> 0 | C32: ='IDENTITAS PENGHUNI RUMAH 2 (2)'!C31 -> 0 | D32: ='IDENTITAS PENGHUNI RUMAH 2 (2)'!D31 -> 0 | E32: ='IDENTITAS PENGHUNI RUMAH 2 (2)'!E31 -> 0
A33: ='IDENTITAS PENGHUNI RUMAH 2 (2)'!A32 -> 21 | B33: ='IDENTITAS PENGHUNI RUMAH 2 (2)'!B32 -> 0 | C33: ='IDENTITAS PENGHUNI RUMAH 2 (2)'!C32 -> 0 | D33: ='IDENTITAS PENGHUNI RUMAH 2 (2)'!D32 -> 0 | E33: ='IDENTITAS PENGHUNI RUMAH 2 (2)'!E32 -> 0
... A112: ='IDENTITAS PENGHUNI RUMAH 2 (2)'!A111 -> 100 | B112: ='IDENTITAS PENGHUNI RUMAH 2 (2)'!B111 -> 0 | C112: ='IDENTITAS PENGHUNI RUMAH 2 (2)'!C111 -> 0 | D112: ='IDENTITAS PENGHUNI RUMAH 2 (2)'!D111 -> 0 | E112: ='IDENTITAS PENGHUNI RUMAH 2 (2)'!E111 -> 0

Sheet KONDISI FISI RUMAH D.2
A1: REKAP PENDATAAN RUMAH TIDAK LAYAK HUNI
A3: ='IDENTITAS PENGHUNI RUMAH 1'!A3 -> Provinsi | C3: ='IDENTITAS PENGHUNI RUMAH 1'!C3 -> Sumatera Selatan
A4: ='IDENTITAS PENGHUNI RUMAH 1'!A4 -> Kota | C4: ='IDENTITAS PENGHUNI RUMAH 1'!C4 -> Palembang
A5: ='IDENTITAS PENGHUNI RUMAH 1'!A5 -> Kecamatan | C5: ='IDENTITAS PENGHUNI RUMAH 1'!C5 -> Plaju
A6: ='IDENTITAS PENGHUNI RUMAH 1'!A6 -> Kelurahan | C6: ='IDENTITAS PENGHUNI RUMAH 1'!C6 -> Talang Putri
A7: ='IDENTITAS PENGHUNI RUMAH 1'!A7 -> Tanggal Pendataan | C7: ='IDENTITAS PENGHUNI RUMAH 1'!C7 -> 0
A9: No | B9: Nama Kepala Rumah Tangga | C9: KONDISI FISIK RUMAH
C10: ASPEK KOMPONEN BAHAN BANGUNAN SESUAI KONTEKS LOKAL
C11: NIK | D11: Alamat | E11: RT/RW | F11: Kondisi Dinding | G11: Material Lantai Terluas | H11: Kondisi Lantai
A13: ='IDENTITAS PENGHUNI RUMAH 2 (2)'!A12 -> 1 | B13: ='IDENTITAS PENGHUNI RUMAH 2 (2)'!B12 -> Sutamak | C13: ='IDENTITAS PENGHUNI RUMAH 2 (2)'!C12 -> 1671140605720003 | D13: ='IDENTITAS PENGHUNI RUMAH 2 (2)'!D12 -> Lrg. Hikmah II | E13: ='IDENTITAS PENGHUNI RUMAH 2 (2)'!E12 -> RT24 RW06 | F13: Rusak Berat/Seluruhnya | G13: Plesteran | H13: Rusak Sedang/Sebagian
A14: ='IDENTITAS PENGHUNI RUMAH 2 (2)'!A13 -> 2 | B14: ='IDENTITAS PENGHUNI RUMAH 2 (2)'!B13 -> Mawarni | C14: ='IDENTITAS PENGHUNI RUMAH 2 (2)'!C13 -> 1671147006690001 | D14: ='IDENTITAS PENGHUNI RUMAH 2 (2)'!D13 -> Lrg. Hikmah II | E14: ='IDENTITAS PENGHUNI RUMAH 2 (2)'!E13 -> RT 24 / RW 06 | F14: Rusak Berat/Seluruhnya | G14: Plesteran | H14: Rusak Ringan
A15: ='IDENTITAS PENGHUNI RUMAH 2 (2)'!A14 -> 3 | B15: ='IDENTITAS PENGHUNI RUMAH 2 (2)'!B14 -> Samsila | C15: ='IDENTITAS PENGHUNI RUMAH 2 (2)'!C14 -> 1.671145e+15 | D15: ='IDENTITAS PENGHUNI RUMAH 2 (2)'!D14 -> Jl. Kapten Robani Kader | E15: ='IDENTITAS PENGHUNI RUMAH 2 (2)'!E14 -> RT 22 / RW 06 | F15: Rusak Berat/Seluruhnya | G15: Kayu | H15: Rusak Berat/Seluruhnya
A16: ='IDENTITAS PENGHUNI RUMAH 2 (2)'!A15 -> 4 | B16: ='IDENTITAS PENGHUNI RUMAH 2 (2)'!B15 -> Sumirah | C16: ='IDENTITAS PENGHUNI RUMAH 2 (2)'!C15 -> 1671146808630004 | D16: ='IDENTITAS PENGHUNI RUMAH 2 (2)'!D15 -> Jl. Kapten Robani Kader | E16: ='IDENTITAS PENGHUNI RUMAH 2 (2)'!E15 -> RT 22 / RW 06 | F16: Rusak Berat/Seluruhnya | G16: Kayu | H16: Rusak Sedang/Sebagian
A17: ='IDENTITAS PENGHUNI RUMAH 2 (2)'!A16 -> 5 | B17: ='IDENTITAS PENGHUNI RUMAH 2 (2)'!B16 -> M. Daud | C17: ='IDENTITAS PENGHUNI RUMAH 2 (2)'!C16 -> 1.6711405e+15 | D17: ='IDENTITAS PENGHUNI RUMAH 2 (2)'!D16 -> Lr. Karya Luhur | E17: ='IDENTITAS PENGHUNI RUMAH 2 (2)'!E16 -> RT 25 RW 06 | F17: Rusak Berat/Seluruhnya | G17: Kayu | H17: Rusak Sedang/Sebagian
A18: ='IDENTITAS PENGHUNI RUMAH 2 (2)'!A17 -> 6 | B18: ='IDENTITAS PENGHUNI RUMAH 2 (2)'!B17 -> Salam Hadi | C18: ='IDENTITAS PENGHUNI RUMAH 2 (2)'!C17 -> 1671141012660005 | D18: ='IDENTITAS PENGHUNI RUMAH 2 (2)'!D17 -> Lrg. Hikmah I | E18: ='IDENTITAS PENGHUNI RUMAH 2 (2)'!E17 -> RT 09 RW 03 | F18: Rusak Berat/Seluruhnya | G18: Kayu | H18: Rusak Sedang/Sebagian
A19: ='IDENTITAS PENGHUNI RUMAH 2 (2)'!A18 -> 7 | B19: ='IDENTITAS PENGHUNI RUMAH 2 (2)'!B18 -> Sukandar | C19: ='IDENTITAS PENGHUNI RUMAH 2 (2)'!C18 -> 1671142101560003 | D19: ='IDENTITAS PENGHUNI RUMAH 2 (2)'!D18 -> Lr. Sidomulyo | E19: ='IDENTITAS PENGHUNI RUMAH 2 (2)'!E18 -> RT12 / RW04 | F19: Rusak Sedang/Sebagian | G19: Kayu | H19: Rusak Sedang/Sebagian
A20: ='IDENTITAS PENGHUNI RUMAH 2 (2)'!A19 -> 8 | B20: ='IDENTITAS PENGHUNI RUMAH 2 (2)'!B19 -> Sagiman | C20: ='IDENTITAS PENGHUNI RUMAH 2 (2)'!C19 -> 1671141408520004 | D20: ='IDENTITAS PENGHUNI RUMAH 2 (2)'!D19 -> Lr.Sidokaton II | E20: ='IDENTITAS PENGHUNI RUMAH 2 (2)'!E19 -> RT09 / RW00 | F20: Rusak Sedang/Sebagian | G20: Plesteran | H20: Rusak Sedang/Sebagian
A21: ='IDENTITAS PENGHUNI RUMAH 2 (2)'!A20 -> 9 | B21: ='IDENTITAS PENGHUNI RUMAH 2 (2)'!B20 -> Daryuni | C21: ='IDENTITAS PENGHUNI RUMAH 2 (2)'!C20 -> 1671145709480003 | D21: ='IDENTITAS PENGHUNI RUMAH 2 (2)'!D20 -> Lr. Karya Luhur | E21: ='IDENTITAS PENGHUNI RUMAH 2 (2)'!E20 -> RT 25 RW 06 | F21: Rusak Sedang/Sebagian | G21: Kayu | H21: Rusak Berat/Seluruhnya
A22: ='IDENTITAS PENGHUNI RUMAH 2 (2)'!A21 -> 10 | B22: ='IDENTITAS PENGHUNI RUMAH 2 (2)'!B21 -> 0 | C22: ='IDENTITAS PENGHUNI RUMAH 2 (2)'!C21 -> 0 | D22: ='IDENTITAS PENGHUNI RUMAH 2 (2)'!D21 -> 0 | E22: ='IDENTITAS PENGHUNI RUMAH 2 (2)'!E21 -> 0
A23: ='IDENTITAS PENGHUNI RUMAH 2 (2)'!A22 -> 11 | B23: ='IDENTITAS PENGHUNI RUMAH 2 (2)'!B22 -> 0 | C23: ='IDENTITAS PENGHUNI RUMAH 2 (2)'!C22 -> 0 | D23: ='IDENTITAS PENGHUNI RUMAH 2 (2)'!D22 -> 0 | E23: ='IDENTITAS PENGHUNI RUMAH 2 (2)'!E22 -> 0
A24: ='IDENTITAS PENGHUNI RUMAH 2 (2)'!A23 -> 12 | B24: ='IDENTITAS PENGHUNI RUMAH 2 (2)'!B23 -> 0 | C24: ='IDENTITAS PENGHUNI RUMAH 2 (2)'!C23 -> 0 | D24: ='IDENTITAS PENGHUNI RUMAH 2 (2)'!D23 -> 0 | E24: ='IDENTITAS PENGHUNI RUMAH 2 (2)'!E23 -> 0
A25: ='IDENTITAS PENGHUNI RUMAH 2 (2)'!A24 -> 13 | B25: ='IDENTITAS PENGHUNI RUMAH 2 (2)'!B24 -> 0 | C25: ='IDENTITAS PENGHUNI RUMAH 2 (2)'!C24 -> 0 | D25: ='IDENTITAS PENGHUNI RUMAH 2 (2)'!D24 -> 0 | E25: ='IDENTITAS PENGHUNI RUMAH 2 (2)'!E24 -> 0
A26: ='IDENTITAS PENGHUNI RUMAH 2 (2)'!A25 -> 14 | B26: ='IDENTITAS PENGHUNI RUMAH 2 (2)'!B25 -> 0 | C26: ='IDENTITAS PENGHUNI RUMAH 2 (2)'!C25 -> 0 | D26: ='IDENTITAS PENGHUNI RUMAH 2 (2)'!D25 -> 0 | E26: ='IDENTITAS PENGHUNI RUMAH 2 (2)'!E25 -> 0
A27: ='IDENTITAS PENGHUNI RUMAH 2 (2)'!A26 -> 15 | B27: ='IDENTITAS PENGHUNI RUMAH 2 (2)'!B26 -> 0 | C27: ='IDENTITAS PENGHUNI RUMAH 2 (2)'!C26 -> 0 | D27: ='IDENTITAS PENGHUNI RUMAH 2 (2)'!D26 -> 0 | E27: ='IDENTITAS PENGHUNI RUMAH 2 (2)'!E26 -> 0
A28: ='IDENTITAS PENGHUNI RUMAH 2 (2)'!A27 -> 16 | B28: ='IDENTITAS PENGHUNI RUMAH 2 (2)'!B27 -> 0 | C28: ='IDENTITAS PENGHUNI RUMAH 2 (2)'!C27 -> 0 | D28: ='IDENTITAS PENGHUNI RUMAH 2 (2)'!D27 -> 0 | E28: ='IDENTITAS PENGHUNI RUMAH 2 (2)'!E27 -> 0
A29: ='IDENTITAS PENGHUNI RUMAH 2 (2)'!A28 -> 17 | B29: ='IDENTITAS PENGHUNI RUMAH 2 (2)'!B28 -> 0 | C29: ='IDENTITAS PENGHUNI RUMAH 2 (2)'!C28 -> 0 | D29: ='IDENTITAS PENGHUNI RUMAH 2 (2)'!D28 -> 0 | E29: ='IDENTITAS PENGHUNI RUMAH 2 (2)'!E28 -> 0
A30: ='IDENTITAS PENGHUNI RUMAH 2 (2)'!A29 -> 18 | B30: ='IDENTITAS PENGHUNI RUMAH 2 (2)'!B29 -> 0 | C30: ='IDENTITAS PENGHUNI RUMAH 2 (2)'!C29 -> 0 | D30: ='IDENTITAS PENGHUNI RUMAH 2 (2)'!D29 -> 0 | E30: ='IDENTITAS PENGHUNI RUMAH 2 (2)'!E29 -> 0
A31: ='IDENTITAS PENGHUNI RUMAH 2 (2)'!A30 -> 19 | B31: ='IDENTITAS PENGHUNI RUMAH 2 (2)'!B30 -> 0 | C31: ='IDENTITAS PENGHUNI RUMAH 2 (2)'!C30 -> 0 | D31: ='IDENTITAS PENGHUNI RUMAH 2 (2)'!D30 -> 0 | E31: ='IDENTITAS PENGHUNI RUMAH 2 (2)'!E30 -> 0
A32: ='IDENTITAS PENGHUNI RUMAH 2 (2)'!A31 -> 20 | B32: ='IDENTITAS PENGHUNI RUMAH 2 (2)'!B31 -> 0 | C32: ='IDENTITAS PENGHUNI RUMAH 2 (2)'!C31 -> 0 | D32: ='IDENTITAS PENGHUNI RUMAH 2 (2)'!D31 -> 0 | E32: ='IDENTITAS PENGHUNI RUMAH 2 (2)'!E31 -> 0
A33: ='IDENTITAS PENGHUNI RUMAH 2 (2)'!A32 -> 21 | B33: ='IDENTITAS PENGHUNI RUMAH 2 (2)'!B32 -> 0 | C33: ='IDENTITAS PENGHUNI RUMAH 2 (2)'!C32 -> 0 | D33: ='IDENTITAS PENGHUNI RUMAH 2 (2)'!D32 -> 0 | E33: ='IDENTITAS PENGHUNI RUMAH 2 (2)'!E32 -> 0
... A112: ='IDENTITAS PENGHUNI RUMAH 2 (2)'!A111 -> 100 | B112: ='IDENTITAS PENGHUNI RUMAH 2 (2)'!B111 -> 0 | C112: ='IDENTITAS PENGHUNI RUMAH 2 (2)'!C111 -> 0 | D112: ='IDENTITAS PENGHUNI RUMAH 2 (2)'!D111 -> 0 | E112: ='IDENTITAS PENGHUNI RUMAH 2 (2)'!E111 -> 0

Sheet LEGALITAS LAHAN DAN PHOTO RUMAH
A1: GAMBAR KONDISI RUMAH TIDAK LAYAK HUNI
A3: Provinsi | C3: ='IDENTITAS PENGHUNI RUMAH 1'!C3 -> Sumatera Selatan
A4: Kota | C4: ='IDENTITAS PENGHUNI RUMAH 1'!C4 -> Palembang
A5: Kecamatan | C5: ='IDENTITAS PENGHUNI RUMAH 1'!C5 -> Plaju
A6: Kelurahan | C6: ='IDENTITAS PENGHUNI RUMAH 1'!C6 -> Talang Putri
A7: Tanggal Pendataan | C7: ='IDENTITAS PENGHUNI RUMAH 1'!C7 -> 0
A9: No | B9: Nama Kepala Rumah Tangga | C9: GAMBAR KONDISI RUMAH TIDAK LAYAH HUNI (RTLH)
C10: NIK | D10: Alamat | E10: RT/RW | F10: Status Kepemilikan Tanah | G10: Titik Ordinat | H10: Photo Rumah
A11: ='IDENTITAS PENGHUNI RUMAH 1'!A12 -> 1 | B11: ='IDENTITAS PENGHUNI RUMAH 1'!B12 -> Sutamak | C11: 1671140605720003 | D11: ='IDENTITAS PENGHUNI RUMAH 1'!D12 -> Lrg. Hikmah II | E11: ='IDENTITAS PENGHUNI RUMAH 1'!E12 -> RT24 RW06 | F11: Milik Sendiri | G11: Longtitude 104°49'22"E
F12: Nomor Sertifikat : | G12: Latitude -3°0'57"S
A13: ='IDENTITAS PENGHUNI RUMAH 1'!A13 -> 2 | B13: ='IDENTITAS PENGHUNI RUMAH 1'!B13 -> Mawarni | C13: 1671147006690001 | D13: ='IDENTITAS PENGHUNI RUMAH 1'!D13 -> Lrg. Hikmah II | E13: ='IDENTITAS PENGHUNI RUMAH 1'!E13 -> RT 24 / RW 06 | F13: Milik Sendiri | G13: Longtitude 104°49'22"E
F14: Nomor Sertifikat : SPH | G14: Latitude -3°0'57"S
A15: ='IDENTITAS PENGHUNI RUMAH 1'!A14 -> 3 | B15: ='IDENTITAS PENGHUNI RUMAH 1'!B14 -> Samsila | C15: 1671145011630010 | D15: ='IDENTITAS PENGHUNI RUMAH 1'!D14 -> Jl. Kapten Robani Kader | E15: ='IDENTITAS PENGHUNI RUMAH 1'!E14 -> RT 22 / RW 06 | F15: Milik Sendiri | G15: Longtitude 104°49'24"E
F16: Nomor Sertifikat : SPH | G16: Latitude -3°0'55"S
A17: ='IDENTITAS PENGHUNI RUMAH 1'!A15 -> 4 | B17: ='IDENTITAS PENGHUNI RUMAH 1'!B15 -> Sumirah | C17: 1671146808630004 | D17: ='IDENTITAS PENGHUNI RUMAH 1'!D15 -> Jl. Kapten Robani Kader | E17: ='IDENTITAS PENGHUNI RUMAH 1'!E15 -> RT 22 / RW 06 | F17: Milik Sendiri | G17: Longtitude 104°49'22"E
F18: Nomor Sertifikat : SPH | G18: Latitude -3°0'55"S
A19: ='IDENTITAS PENGHUNI RUMAH 1'!A16 -> 5 | B19: ='IDENTITAS PENGHUNI RUMAH 1'!B16 -> M. Daud | C19: 1671140508590010 | D19: ='IDENTITAS PENGHUNI RUMAH 1'!D16 -> Lr. Karya Luhur | E19: ='IDENTITAS PENGHUNI RUMAH 1'!E16 -> RT 25 RW 06 | F19: Milik Sendiri | G19: Longtitude 104°49'22"E
F20: Nomor Sertifikat : SPH | G20: Latitude -3°0'56"S
A21: ='IDENTITAS PENGHUNI RUMAH 1'!A17 -> 6 | B21: ='IDENTITAS PENGHUNI RUMAH 1'!B17 -> Salam Hadi | C21: 1671141012660005 | D21: ='IDENTITAS PENGHUNI RUMAH 1'!D17 -> Lrg. Hikmah I | E21: ='IDENTITAS PENGHUNI RUMAH 1'!E17 -> RT 09 RW 03 | F21: Milik Sendiri | G21: Longtitude 104°49'22"E
F22: Nomor Sertifikat : SPH | G22: Latitude -3°0'56"S
A23: ='IDENTITAS PENGHUNI RUMAH 1'!A18 -> 7 | B23: ='IDENTITAS PENGHUNI RUMAH 1'!B18 -> Sukandar | C23: 1671142101560003 | D23: ='IDENTITAS PENGHUNI RUMAH 1'!D18 -> Lr. Sidomulyo | E23: ='IDENTITAS PENGHUNI RUMAH 1'!E18 -> RT12 / RW04 | F23: Milik Sendiri | G23: Longtitude 104°49'13"E
F24: Nomor Sertifikat : SPH | G24: Latitude -3°0'44"S
A25: ='IDENTITAS PENGHUNI RUMAH 1'!A19 -> 8 | B25: ='IDENTITAS PENGHUNI RUMAH 1'!B19 -> Sagiman | C25: 1671141408520004 | D25: ='IDENTITAS PENGHUNI RUMAH 1'!D19 -> Lr.Sidokaton II | E25: ='IDENTITAS PENGHUNI RUMAH 1'!E19 -> RT09 / RW00 | F25: Milik Sendiri | G25: Longtitude 104°49'6"E
F26: Nomor Sertifikat : SPH | G26: Latitude -3°0'30"S
A27: ='IDENTITAS PENGHUNI RUMAH 1'!A20 -> 9 | B27: ='IDENTITAS PENGHUNI RUMAH 1'!B20 -> Daryuni | C27: 1671145709480003 | D27: ='IDENTITAS PENGHUNI RUMAH 1'!D20 -> Lr. Karya Luhur | E27: ='IDENTITAS PENGHUNI RUMAH 1'!E20 -> RT 25 RW 06 | F27: Milik Sendiri | G27: Longtitude 104°49'15"E
F28: Nomor Sertifikat : SPH | G28: Latitude -3°1'12"S
A29: ='IDENTITAS PENGHUNI RUMAH 1'!A21 -> 10 | B29: ='IDENTITAS PENGHUNI RUMAH 1'!B21 -> 0 | C29: ='IDENTITAS PENGHUNI RUMAH 1'!C21 -> 0 | D29: ='IDENTITAS PENGHUNI RUMAH 1'!D21 -> 0 | E29: ='IDENTITAS PENGHUNI RUMAH 1'!E21 -> 0
F30: Nomor Sertifikat :
A31: ='IDENTITAS PENGHUNI RUMAH 1'!A22 -> 11 | B31: ='IDENTITAS PENGHUNI RUMAH 1'!B22 -> 0 | C31: ='IDENTITAS PENGHUNI RUMAH 1'!C22 -> 0 | D31: ='IDENTITAS PENGHUNI RUMAH 1'!D22 -> 0 | E31: ='IDENTITAS PENGHUNI RUMAH 1'!E22 -> 0
F32: Nomor Sertifikat :
A33: ='IDENTITAS PENGHUNI RUMAH 1'!A23 -> 12 | B33: ='IDENTITAS PENGHUNI RUMAH 1'!B23 -> 0 | C33: ='IDENTITAS PENGHUNI RUMAH 1'!C23 -> 0 | D33: ='IDENTITAS PENGHUNI RUMAH 1'!D23 -> 0 | E33: ='IDENTITAS PENGHUNI RUMAH 1'!E23 -> 0
F34: Nomor Sertifikat :
A35: ='IDENTITAS PENGHUNI RUMAH 1'!A24 -> 13 | B35: ='IDENTITAS PENGHUNI RUMAH 1'!B24 -> 0 | C35: ='IDENTITAS PENGHUNI RUMAH 1'!C24 -> 0 | D35: ='IDENTITAS PENGHUNI RUMAH 1'!D24 -> 0 | E35: ='IDENTITAS PENGHUNI RUMAH 1'!E24 -> 0
F36: Nomor Sertifikat :
A37: ='IDENTITAS PENGHUNI RUMAH 1'!A25 -> 14 | B37: ='IDENTITAS PENGHUNI RUMAH 1'!B25 -> 0 | C37: ='IDENTITAS PENGHUNI RUMAH 1'!C25 -> 0 | D37: ='IDENTITAS PENGHUNI RUMAH 1'!D25 -> 0 | E37: ='IDENTITAS PENGHUNI RUMAH 1'!E25 -> 0
F38: Nomor Sertifikat :
A39: ='IDENTITAS PENGHUNI RUMAH 1'!A26 -> 15 | B39: ='IDENTITAS PENGHUNI RUMAH 1'!B26 -> 0 | C39: ='IDENTITAS PENGHUNI RUMAH 1'!C26 -> 0 | D39: ='IDENTITAS PENGHUNI RUMAH 1'!D26 -> 0 | E39: ='IDENTITAS PENGHUNI RUMAH 1'!E26 -> 0
F40: Nomor Sertifikat :
A41: ='IDENTITAS PENGHUNI RUMAH 1'!A27 -> 16 | B41: ='IDENTITAS PENGHUNI RUMAH 1'!B27 -> 0 | C41: ='IDENTITAS PENGHUNI RUMAH 1'!C27 -> 0 | D41: ='IDENTITAS PENGHUNI RUMAH 1'!D27 -> 0 | E41: ='IDENTITAS PENGHUNI RUMAH 1'!E27 -> 0
F42: Nomor Sertifikat :
...
